Workbook

Sheet 프로젝트WBS
B1: 물류센터 자동 분류, 파레타이징, 출하 디지털 트윈 WBS | K1: 실적기준일 : | L1: 46322 | T1: SPI | U1: =IFERROR(U5/S5,0) -> 0.5443787 | V1: =IF(U1<0.75,"(위험)",IF(U1<0.85,"(경고)",IF(U1<0.95,"(주의)","(양호)"))) -> (위험)
B3: 단계 | F3: TASK | G3: 범위 | H3: 담당 | I3: 산출물 | J3: 완료 조건 (TC) | K3: 계획 시작일 | L3: 예상 완료일 | M3: 실제 시작일 | N3: 실제 완료(예정)일 | O3: 계획 기간 | P3: 실제 기간 | Q3: 계획 진행 | R3: 실제 진행 | S3: 계획 완료율 | T3: 작업 완료율 | U3: 프로젝트 실적 | W3: 10일 개발 일정 (10/27~11/5)
U4: 진척율 | V4: 달성율 | W4: 26. 10월 | AB4: 26. 11월
C5: 가중치 | D5: 수행단계 | K5: =MIN(K6:K107) -> 46322 | L5: =MAX(L6:L107) -> 46331 | M5: =MIN(M6:M107) -> 46322 | N5: =MAX(N6:N107) -> 46322 | O5: =O108 -> 92 | P5: =P108 -> 10 | Q5: =Q108 -> 13 | R5: =R108 -> 10 | S5: =S108 -> 0.14130435 | T5: =T108 -> 0.10869565 | U5: =AVERAGE(U6:U18)*C6+AVERAGE(U20:U40)*C20+AVERAGE(U42:U64)*C42+AVERAGE(U66:U82)*C66+AVERAGE(U84:U95)*C84+AVERAGE(U97:U100)*C97 -> 0.076923077 | V5: =U5-S5 -> -0.064381271 | W5: 46322 | X5: 46323 | Y5: 46324 | Z5: 46325 | AA5: 46326 | AB5: 46327 | AC5: 46328 | AD5: 46329 | AE5: 46330 | AF5: 46331
B6: 1 | C6: 0.1 | D6: 기획/문서/에셋 | E6: FR-01~FR-24 NFR-01~NFR-07 | F6: SRS v1.1 요구사항과 TC 번호 확정 | G6: 필수 | H6: 이영노 | I6: SRS_LogisticsCenter_v1.1.docx | J6: FR-01~FR-24, NFR-01~NFR-07이 TC-01~TC-31에 1:1로 연결됨 | K6: 46322 | L6: 46322 | M6: 46322 | N6: 46322 | O6: =IF(OR(K6="",L6=""),0,L6-K6+1-COUNTIFS(휴일!$A$2:$A$20,">="&K6,휴일!$A$2:$A$20,"<="&L6)) -> 1 | P6: =IF(OR(M6="",N6=""),0,N6-M6+1-COUNTIFS(휴일!$A$2:$A$20,">="&M6,휴일!$A$2:$A$20,"<="&N6)) -> 1 | Q6: =IF(O6=0,0,MAX(0,MIN(O6,$L$1-K6+1-COUNTIFS(휴일!$A$2:$A$20,">="&K6,휴일!$A$2:$A$20,"<="&$L$1)))) -> 1 | R6: =IF(P6=0,0,MIN(P6,O6)) -> 1 | S6: =IFERROR(Q6/O6,0) -> 1 | T6: =IFERROR(R6/O6,0) -> 1 | U6: =IF(OR(O6=0,R6=0),0,MIN(1,R6/O6)) -> 1 | V6: =U6-S6 -> 0 | W6: =IF(AND(W$5>=$K6,W$5<=$L6,COUNTIF(휴일!$A$2:$A$20,W$5)=0),IF($G6="선택","□","■"),"") -> ■ | X6: =IF(AND(X$5>=$K6,X$5<=$L6,COUNTIF(휴일!$A$2:$A$20,X$5)=0),IF($G6="선택","□","■"),"") | Y6: =IF(AND(Y$5>=$K6,Y$5<=$L6,COUNTIF(휴일!$A$2:$A$20,Y$5)=0),IF($G6="선택","□","■"),"") | Z6: =IF(AND(Z$5>=$K6,Z$5<=$L6,COUNTIF(휴일!$A$2:$A$20,Z$5)=0),IF($G6="선택","□","■"),"") | AA6: =IF(AND(AA$5>=$K6,AA$5<=$L6,COUNTIF(휴일!$A$2:$A$20,AA$5)=0),IF($G6="선택","□","■"),"") | AB6: =IF(AND(AB$5>=$K6,AB$5<=$L6,COUNTIF(휴일!$A$2:$A$20,AB$5)=0),IF($G6="선택","□","■"),"") | AC6: =IF(AND(AC$5>=$K6,AC$5<=$L6,COUNTIF(휴일!$A$2:$A$20,AC$5)=0),IF($G6="선택","□","■"),"") | AD6: =IF(AND(AD$5>=$K6,AD$5<=$L6,COUNTIF(휴일!$A$2:$A$20,AD$5)=0),IF($G6="선택","□","■"),"") | ... AF6: =IF(AND(AF$5>=$K6,AF$5<=$L6,COUNTIF(휴일!$A$2:$A$20,AF$5)=0),IF($G6="선택","□","■"),"")
E7: FR-01~FR-24 NFR-01~NFR-07 | F7: SRS 기준 WBS 작성 | G7: 필수 | H7: 이영노 | I7: WBS_LogisticsCenter.xlsx | J7: 모든 FR과 NFR이 작업과 완료 조건의 TC에 연결됨 | K7: 46322 | L7: 46322 | M7: 46322 | N7: 46322 | O7: =IF(OR(K7="",L7=""),0,L7-K7+1-COUNTIFS(휴일!$A$2:$A$20,">="&K7,휴일!$A$2:$A$20,"<="&L7)) -> 1 | P7: =IF(OR(M7="",N7=""),0,N7-M7+1-COUNTIFS(휴일!$A$2:$A$20,">="&M7,휴일!$A$2:$A$20,"<="&N7)) -> 1 | Q7: =IF(O7=0,0,MAX(0,MIN(O7,$L$1-K7+1-COUNTIFS(휴일!$A$2:$A$20,">="&K7,휴일!$A$2:$A$20,"<="&$L$1)))) -> 1 | R7: =IF(P7=0,0,MIN(P7,O7)) -> 1 | S7: =IFERROR(Q7/O7,0) -> 1 | T7: =IFERROR(R7/O7,0) -> 1 | U7: =IF(OR(O7=0,R7=0),0,MIN(1,R7/O7)) -> 1 | V7: =U7-S7 -> 0 | W7: =IF(AND(W$5>=$K7,W$5<=$L7,COUNTIF(휴일!$A$2:$A$20,W$5)=0),IF($G7="선택","□","■"),"") -> ■ | X7: =IF(AND(X$5>=$K7,X$5<=$L7,COUNTIF(휴일!$A$2:$A$20,X$5)=0),IF($G7="선택","□","■"),"") | Y7: =IF(AND(Y$5>=$K7,Y$5<=$L7,COUNTIF(휴일!$A$2:$A$20,Y$5)=0),IF($G7="선택","□","■"),"") | Z7: =IF(AND(Z$5>=$K7,Z$5<=$L7,COUNTIF(휴일!$A$2:$A$20,Z$5)=0),IF($G7="선택","□","■"),"") | AA7: =IF(AND(AA$5>=$K7,AA$5<=$L7,COUNTIF(휴일!$A$2:$A$20,AA$5)=0),IF($G7="선택","□","■"),"") | AB7: =IF(AND(AB$5>=$K7,AB$5<=$L7,COUNTIF(휴일!$A$2:$A$20,AB$5)=0),IF($G7="선택","□","■"),"") | AC7: =IF(AND(AC$5>=$K7,AC$5<=$L7,COUNTIF(휴일!$A$2:$A$20,AC$5)=0),IF($G7="선택","□","■"),"") | AD7: =IF(AND(AD$5>=$K7,AD$5<=$L7,COUNTIF(휴일!$A$2:$A$20,AD$5)=0),IF($G7="선택","□","■"),"") | ... AF7: =IF(AND(AF$5>=$K7,AF$5<=$L7,COUNTIF(휴일!$A$2:$A$20,AF$5)=0),IF($G7="선택","□","■"),"")
E8: FR-01 | F8: 물류센터 건물 에셋 준비 | G8: 필수 | H8: 이영노 | I8: 건물 Prefab | J8: 외벽, 바닥, 출입구 모델이 Unity에 Import됨 | K8: 46322 | L8: 46322 | M8: 46322 | N8: 46322 | O8: =IF(OR(K8="",L8=""),0,L8-K8+1-COUNTIFS(휴일!$A$2:$A$20,">="&K8,휴일!$A$2:$A$20,"<="&L8)) -> 1 | P8: =IF(OR(M8="",N8=""),0,N8-M8+1-COUNTIFS(휴일!$A$2:$A$20,">="&M8,휴일!$A$2:$A$20,"<="&N8)) -> 1 | Q8: =IF(O8=0,0,MAX(0,MIN(O8,$L$1-K8+1-COUNTIFS(휴일!$A$2:$A$20,">="&K8,휴일!$A$2:$A$20,"<="&$L$1)))) -> 1 | R8: =IF(P8=0,0,MIN(P8,O8)) -> 1 | S8: =IFERROR(Q8/O8,0) -> 1 | T8: =IFERROR(R8/O8,0) -> 1 | U8: =IF(OR(O8=0,R8=0),0,MIN(1,R8/O8)) -> 1 | V8: =U8-S8 -> 0 | W8: =IF(AND(W$5>=$K8,W$5<=$L8,COUNTIF(휴일!$A$2:$A$20,W$5)=0),IF($G8="선택","□","■"),"") -> ■ | X8: =IF(AND(X$5>=$K8,X$5<=$L8,COUNTIF(휴일!$A$2:$A$20,X$5)=0),IF($G8="선택","□","■"),"") | Y8: =IF(AND(Y$5>=$K8,Y$5<=$L8,COUNTIF(휴일!$A$2:$A$20,Y$5)=0),IF($G8="선택","□","■"),"") | Z8: =IF(AND(Z$5>=$K8,Z$5<=$L8,COUNTIF(휴일!$A$2:$A$20,Z$5)=0),IF($G8="선택","□","■"),"") | AA8: =IF(AND(AA$5>=$K8,AA$5<=$L8,COUNTIF(휴일!$A$2:$A$20,AA$5)=0),IF($G8="선택","□","■"),"") | AB8: =IF(AND(AB$5>=$K8,AB$5<=$L8,COUNTIF(휴일!$A$2:$A$20,AB$5)=0),IF($G8="선택","□","■"),"") | AC8: =IF(AND(AC$5>=$K8,AC$5<=$L8,COUNTIF(휴일!$A$2:$A$20,AC$5)=0),IF($G8="선택","□","■"),"") | AD8: =IF(AND(AD$5>=$K8,AD$5<=$L8,COUNTIF(휴일!$A$2:$A$20,AD$5)=0),IF($G8="선택","□","■"),"") | ... AF8: =IF(AND(AF$5>=$K8,AF$5<=$L8,COUNTIF(휴일!$A$2:$A$20,AF$5)=0),IF($G8="선택","□","■"),"")
E9: FR-05 | F9: 메인 컨베이어 에셋 준비 | G9: 필수 | H9: 이영노 | I9: 컨베이어 Prefab | J9: 직선과 곡선 구간 모델이 Unity에 Import됨 | K9: 46322 | L9: 46322 | M9: 46322 | N9: 46322 | O9: =IF(OR(K9="",L9=""),0,L9-K9+1-COUNTIFS(휴일!$A$2:$A$20,">="&K9,휴일!$A$2:$A$20,"<="&L9)) -> 1 | P9: =IF(OR(M9="",N9=""),0,N9-M9+1-COUNTIFS(휴일!$A$2:$A$20,">="&M9,휴일!$A$2:$A$20,"<="&N9)) -> 1 | Q9: =IF(O9=0,0,MAX(0,MIN(O9,$L$1-K9+1-COUNTIFS(휴일!$A$2:$A$20,">="&K9,휴일!$A$2:$A$20,"<="&$L$1)))) -> 1 | R9: =IF(P9=0,0,MIN(P9,O9)) -> 1 | S9: =IFERROR(Q9/O9,0) -> 1 | T9: =IFERROR(R9/O9,0) -> 1 | U9: =IF(OR(O9=0,R9=0),0,MIN(1,R9/O9)) -> 1 | V9: =U9-S9 -> 0 | W9: =IF(AND(W$5>=$K9,W$5<=$L9,COUNTIF(휴일!$A$2:$A$20,W$5)=0),IF($G9="선택","□","■"),"") -> ■ | X9: =IF(AND(X$5>=$K9,X$5<=$L9,COUNTIF(휴일!$A$2:$A$20,X$5)=0),IF($G9="선택","□","■"),"") | Y9: =IF(AND(Y$5>=$K9,Y$5<=$L9,COUNTIF(휴일!$A$2:$A$20,Y$5)=0),IF($G9="선택","□","■"),"") | Z9: =IF(AND(Z$5>=$K9,Z$5<=$L9,COUNTIF(휴일!$A$2:$A$20,Z$5)=0),IF($G9="선택","□","■"),"") | AA9: =IF(AND(AA$5>=$K9,AA$5<=$L9,COUNTIF(휴일!$A$2:$A$20,AA$5)=0),IF($G9="선택","□","■"),"") | AB9: =IF(AND(AB$5>=$K9,AB$5<=$L9,COUNTIF(휴일!$A$2:$A$20,AB$5)=0),IF($G9="선택","□","■"),"") | AC9: =IF(AND(AC$5>=$K9,AC$5<=$L9,COUNTIF(휴일!$A$2:$A$20,AC$5)=0),IF($G9="선택","□","■"),"") | AD9: =IF(AND(AD$5>=$K9,AD$5<=$L9,COUNTIF(휴일!$A$2:$A$20,AD$5)=0),IF($G9="선택","□","■"),"") | ... AF9: =IF(AND(AF$5>=$K9,AF$5<=$L9,COUNTIF(휴일!$A$2:$A$20,AF$5)=0),IF($G9="선택","□","■"),"")
E10: FR-08 | F10: 경사 롤러 컨베이어 에셋 준비 | G10: 필수 | H10: 이영노 | I10: 롤러 Prefab | J10: 구동부 없는 롤러 모델이 Unity에 Import됨 | K10: 46322 | L10: 46322 | M10: 46322 | N10: 46322 | O10: =IF(OR(K10="",L10=""),0,L10-K10+1-COUNTIFS(휴일!$A$2:$A$20,">="&K10,휴일!$A$2:$A$20,"<="&L10)) -> 1 | P10: =IF(OR(M10="",N10=""),0,N10-M10+1-COUNTIFS(휴일!$A$2:$A$20,">="&M10,휴일!$A$2:$A$20,"<="&N10)) -> 1 | Q10: =IF(O10=0,0,MAX(0,MIN(O10,$L$1-K10+1-COUNTIFS(휴일!$A$2:$A$20,">="&K10,휴일!$A$2:$A$20,"<="&$L$1)))) -> 1 | R10: =IF(P10=0,0,MIN(P10,O10)) -> 1 | S10: =IFERROR(Q10/O10,0) -> 1 | T10: =IFERROR(R10/O10,0) -> 1 | U10: =IF(OR(O10=0,R10=0),0,MIN(1,R10/O10)) -> 1 | V10: =U10-S10 -> 0 | W10: =IF(AND(W$5>=$K10,W$5<=$L10,COUNTIF(휴일!$A$2:$A$20,W$5)=0),IF($G10="선택","□","■"),"") -> ■ | X10: =IF(AND(X$5>=$K10,X$5<=$L10,COUNTIF(휴일!$A$2:$A$20,X$5)=0),IF($G10="선택","□","■"),"") | Y10: =IF(AND(Y$5>=$K10,Y$5<=$L10,COUNTIF(휴일!$A$2:$A$20,Y$5)=0),IF($G10="선택","□","■"),"") | Z10: =IF(AND(Z$5>=$K10,Z$5<=$L10,COUNTIF(휴일!$A$2:$A$20,Z$5)=0),IF($G10="선택","□","■"),"") | AA10: =IF(AND(AA$5>=$K10,AA$5<=$L10,COUNTIF(휴일!$A$2:$A$20,AA$5)=0),IF($G10="선택","□","■"),"") | AB10: =IF(AND(AB$5>=$K10,AB$5<=$L10,COUNTIF(휴일!$A$2:$A$20,AB$5)=0),IF($G10="선택","□","■"),"") | AC10: =IF(AND(AC$5>=$K10,AC$5<=$L10,COUNTIF(휴일!$A$2:$A$20,AC$5)=0),IF($G10="선택","□","■"),"") | AD10: =IF(AND(AD$5>=$K10,AD$5<=$L10,COUNTIF(휴일!$A$2:$A$20,AD$5)=0),IF($G10="선택","□","■"),"") | ... AF10: =IF(AND(AF$5>=$K10,AF$5<=$L10,COUNTIF(휴일!$A$2:$A$20,AF$5)=0),IF($G10="선택","□","■"),"")
E11: FR-03 | F11: 박스 모델 준비 | G11: 필수 | H11: 이영노 | I11: 박스 Prefab | J11: 360×280×340mm, 2kg 박스 모델 생성 | K11: 46322 | L11: 46322 | M11: 46322 | N11: 46322 | O11: =IF(OR(K11="",L11=""),0,L11-K11+1-COUNTIFS(휴일!$A$2:$A$20,">="&K11,휴일!$A$2:$A$20,"<="&L11)) -> 1 | P11: =IF(OR(M11="",N11=""),0,N11-M11+1-COUNTIFS(휴일!$A$2:$A$20,">="&M11,휴일!$A$2:$A$20,"<="&N11)) -> 1 | Q11: =IF(O11=0,0,MAX(0,MIN(O11,$L$1-K11+1-COUNTIFS(휴일!$A$2:$A$20,">="&K11,휴일!$A$2:$A$20,"<="&$L$1)))) -> 1 | R11: =IF(P11=0,0,MIN(P11,O11)) -> 1 | S11: =IFERROR(Q11/O11,0) -> 1 | T11: =IFERROR(R11/O11,0) -> 1 | U11: =IF(OR(O11=0,R11=0),0,MIN(1,R11/O11)) -> 1 | V11: =U11-S11 -> 0 | W11: =IF(AND(W$5>=$K11,W$5<=$L11,COUNTIF(휴일!$A$2:$A$20,W$5)=0),IF($G11="선택","□","■"),"") -> ■ | X11: =IF(AND(X$5>=$K11,X$5<=$L11,COUNTIF(휴일!$A$2:$A$20,X$5)=0),IF($G11="선택","□","■"),"") | Y11: =IF(AND(Y$5>=$K11,Y$5<=$L11,COUNTIF(휴일!$A$2:$A$20,Y$5)=0),IF($G11="선택","□","■"),"") | Z11: =IF(AND(Z$5>=$K11,Z$5<=$L11,COUNTIF(휴일!$A$2:$A$20,Z$5)=0),IF($G11="선택","□","■"),"") | AA11: =IF(AND(AA$5>=$K11,AA$5<=$L11,COUNTIF(휴일!$A$2:$A$20,AA$5)=0),IF($G11="선택","□","■"),"") | AB11: =IF(AND(AB$5>=$K11,AB$5<=$L11,COUNTIF(휴일!$A$2:$A$20,AB$5)=0),IF($G11="선택","□","■"),"") | AC11: =IF(AND(AC$5>=$K11,AC$5<=$L11,COUNTIF(휴일!$A$2:$A$20,AC$5)=0),IF($G11="선택","□","■"),"") | AD11: =IF(AND(AD$5>=$K11,AD$5<=$L11,COUNTIF(휴일!$A$2:$A$20,AD$5)=0),IF($G11="선택","□","■"),"") | ... AF11: =IF(AND(AF$5>=$K11,AF$5<=$L11,COUNTIF(휴일!$A$2:$A$20,AF$5)=0),IF($G11="선택","□","■"),"")
E12: FR-10 | F12: 파레트 모델 준비 | G12: 필수 | H12: 이영노 | I12: 파레트 Prefab | J12: 1100×1100×150mm 파레트 모델 생성 | K12: 46322 | L12: 46322 | M12: 46322 | O12: =IF(OR(K12="",L12=""),0,L12-K12+1-COUNTIFS(휴일!$A$2:$A$20,">="&K12,휴일!$A$2:$A$20,"<="&L12)) -> 1 | P12: =IF(OR(M12="",N12=""),0,N12-M12+1-COUNTIFS(휴일!$A$2:$A$20,">="&M12,휴일!$A$2:$A$20,"<="&N12)) -> 0 | Q12: =IF(O12=0,0,MAX(0,MIN(O12,$L$1-K12+1-COUNTIFS(휴일!$A$2:$A$20,">="&K12,휴일!$A$2:$A$20,"<="&$L$1)))) -> 1 | R12: =IF(P12=0,0,MIN(P12,O12)) -> 0 | S12: =IFERROR(Q12/O12,0) -> 1 | T12: =IFERROR(R12/O12,0) -> 0 | U12: =IF(OR(O12=0,R12=0),0,MIN(1,R12/O12)) -> 0 | V12: =U12-S12 -> -1 | W12: =IF(AND(W$5>=$K12,W$5<=$L12,COUNTIF(휴일!$A$2:$A$20,W$5)=0),IF($G12="선택","□","■"),"") -> ■ | X12: =IF(AND(X$5>=$K12,X$5<=$L12,COUNTIF(휴일!$A$2:$A$20,X$5)=0),IF($G12="선택","□","■"),"") | Y12: =IF(AND(Y$5>=$K12,Y$5<=$L12,COUNTIF(휴일!$A$2:$A$20,Y$5)=0),IF($G12="선택","□","■"),"") | Z12: =IF(AND(Z$5>=$K12,Z$5<=$L12,COUNTIF(휴일!$A$2:$A$20,Z$5)=0),IF($G12="선택","□","■"),"") | AA12: =IF(AND(AA$5>=$K12,AA$5<=$L12,COUNTIF(휴일!$A$2:$A$20,AA$5)=0),IF($G12="선택","□","■"),"") | AB12: =IF(AND(AB$5>=$K12,AB$5<=$L12,COUNTIF(휴일!$A$2:$A$20,AB$5)=0),IF($G12="선택","□","■"),"") | AC12: =IF(AND(AC$5>=$K12,AC$5<=$L12,COUNTIF(휴일!$A$2:$A$20,AC$5)=0),IF($G12="선택","□","■"),"") | AD12: =IF(AND(AD$5>=$K12,AD$5<=$L12,COUNTIF(휴일!$A$2:$A$20,AD$5)=0),IF($G12="선택","□","■"),"") | ... AF12: =IF(AND(AF$5>=$K12,AF$5<=$L12,COUNTIF(휴일!$A$2:$A$20,AF$5)=0),IF($G12="선택","□","■"),"")
E13: FR-10 | F13: FR5 URDF와 STL Import | G13: 필수 | H13: 이영노 | I13: FR5 Prefab | J13: fairino5_v6 관절 제한과 링크 형상 반영. 파일 사용 권리 확인 결과 기록 | K13: 46322 | L13: 46322 | M13: 46322 | N13: 46322 | O13: =IF(OR(K13="",L13=""),0,L13-K13+1-COUNTIFS(휴일!$A$2:$A$20,">="&K13,휴일!$A$2:$A$20,"<="&L13)) -> 1 | P13: =IF(OR(M13="",N13=""),0,N13-M13+1-COUNTIFS(휴일!$A$2:$A$20,">="&M13,휴일!$A$2:$A$20,"<="&N13)) -> 1 | Q13: =IF(O13=0,0,MAX(0,MIN(O13,$L$1-K13+1-COUNTIFS(휴일!$A$2:$A$20,">="&K13,휴일!$A$2:$A$20,"<="&$L$1)))) -> 1 | R13: =IF(P13=0,0,MIN(P13,O13)) -> 1 | S13: =IFERROR(Q13/O13,0) -> 1 | T13: =IFERROR(R13/O13,0) -> 1 | U13: =IF(OR(O13=0,R13=0),0,MIN(1,R13/O13)) -> 1 | V13: =U13-S13 -> 0 | W13: =IF(AND(W$5>=$K13,W$5<=$L13,COUNTIF(휴일!$A$2:$A$20,W$5)=0),IF($G13="선택","□","■"),"") -> ■ | X13: =IF(AND(X$5>=$K13,X$5<=$L13,COUNTIF(휴일!$A$2:$A$20,X$5)=0),IF($G13="선택","□","■"),"") | Y13: =IF(AND(Y$5>=$K13,Y$5<=$L13,COUNTIF(휴일!$A$2:$A$20,Y$5)=0),IF($G13="선택","□","■"),"") | Z13: =IF(AND(Z$5>=$K13,Z$5<=$L13,COUNTIF(휴일!$A$2:$A$20,Z$5)=0),IF($G13="선택","□","■"),"") | AA13: =IF(AND(AA$5>=$K13,AA$5<=$L13,COUNTIF(휴일!$A$2:$A$20,AA$5)=0),IF($G13="선택","□","■"),"") | AB13: =IF(AND(AB$5>=$K13,AB$5<=$L13,COUNTIF(휴일!$A$2:$A$20,AB$5)=0),IF($G13="선택","□","■"),"") | AC13: =IF(AND(AC$5>=$K13,AC$5<=$L13,COUNTIF(휴일!$A$2:$A$20,AC$5)=0),IF($G13="선택","□","■"),"") | AD13: =IF(AND(AD$5>=$K13,AD$5<=$L13,COUNTIF(휴일!$A$2:$A$20,AD$5)=0),IF($G13="선택","□","■"),"") | ... AF13: =IF(AND(AF$5>=$K13,AF$5<=$L13,COUNTIF(휴일!$A$2:$A$20,AF$5)=0),IF($G13="선택","□","■"),"")
E14: FR-09 | F14: 흡착 툴 모델 준비 | G14: 필수 | H14: 이영노 | I14: 흡착 툴 Prefab | J14: 툴 길이 182.8mm 반영, FR5 플랜지에 장착됨 | K14: 46322 | L14: 46322 | M14: 46322 | N14: 46322 | O14: =IF(OR(K14="",L14=""),0,L14-K14+1-COUNTIFS(휴일!$A$2:$A$20,">="&K14,휴일!$A$2:$A$20,"<="&L14)) -> 1 | P14: =IF(OR(M14="",N14=""),0,N14-M14+1-COUNTIFS(휴일!$A$2:$A$20,">="&M14,휴일!$A$2:$A$20,"<="&N14)) -> 1 | Q14: =IF(O14=0,0,MAX(0,MIN(O14,$L$1-K14+1-COUNTIFS(휴일!$A$2:$A$20,">="&K14,휴일!$A$2:$A$20,"<="&$L$1)))) -> 1 | R14: =IF(P14=0,0,MIN(P14,O14)) -> 1 | S14: =IFERROR(Q14/O14,0) -> 1 | T14: =IFERROR(R14/O14,0) -> 1 | U14: =IF(OR(O14=0,R14=0),0,MIN(1,R14/O14)) -> 1 | V14: =U14-S14 -> 0 | W14: =IF(AND(W$5>=$K14,W$5<=$L14,COUNTIF(휴일!$A$2:$A$20,W$5)=0),IF($G14="선택","□","■"),"") -> ■ | X14: =IF(AND(X$5>=$K14,X$5<=$L14,COUNTIF(휴일!$A$2:$A$20,X$5)=0),IF($G14="선택","□","■"),"") | Y14: =IF(AND(Y$5>=$K14,Y$5<=$L14,COUNTIF(휴일!$A$2:$A$20,Y$5)=0),IF($G14="선택","□","■"),"") | Z14: =IF(AND(Z$5>=$K14,Z$5<=$L14,COUNTIF(휴일!$A$2:$A$20,Z$5)=0),IF($G14="선택","□","■"),"") | AA14: =IF(AND(AA$5>=$K14,AA$5<=$L14,COUNTIF(휴일!$A$2:$A$20,AA$5)=0),IF($G14="선택","□","■"),"") | AB14: =IF(AND(AB$5>=$K14,AB$5<=$L14,COUNTIF(휴일!$A$2:$A$20,AB$5)=0),IF($G14="선택","□","■"),"") | AC14: =IF(AND(AC$5>=$K14,AC$5<=$L14,COUNTIF(휴일!$A$2:$A$20,AC$5)=0),IF($G14="선택","□","■"),"") | AD14: =IF(AND(AD$5>=$K14,AD$5<=$L14,COUNTIF(휴일!$A$2:$A$20,AD$5)=0),IF($G14="선택","□","■"),"") | ... AF14: =IF(AND(AF$5>=$K14,AF$5<=$L14,COUNTIF(휴일!$A$2:$A$20,AF$5)=0),IF($G14="선택","□","■"),"")
E15: FR-13, FR-14 | F15: AMR 지게차 모델 준비 | G15: 필수 | H15: 이영노 | I15: AMR Prefab | J15: 포크로 파레트를 들 수 있는 모델이 Import됨 | K15: 46322 | L15: 46322 | M15: 46322 | O15: =IF(OR(K15="",L15=""),0,L15-K15+1-COUNTIFS(휴일!$A$2:$A$20,">="&K15,휴일!$A$2:$A$20,"<="&L15)) -> 1 | P15: =IF(OR(M15="",N15=""),0,N15-M15+1-COUNTIFS(휴일!$A$2:$A$20,">="&M15,휴일!$A$2:$A$20,"<="&N15)) -> 0 | Q15: =IF(O15=0,0,MAX(0,MIN(O15,$L$1-K15+1-COUNTIFS(휴일!$A$2:$A$20,">="&K15,휴일!$A$2:$A$20,"<="&$L$1)))) -> 1 | R15: =IF(P15=0,0,MIN(P15,O15)) -> 0 | S15: =IFERROR(Q15/O15,0) -> 1 | T15: =IFERROR(R15/O15,0) -> 0 | U15: =IF(OR(O15=0,R15=0),0,MIN(1,R15/O15)) -> 0 | V15: =U15-S15 -> -1 | W15: =IF(AND(W$5>=$K15,W$5<=$L15,COUNTIF(휴일!$A$2:$A$20,W$5)=0),IF($G15="선택","□","■"),"") -> ■ | X15: =IF(AND(X$5>=$K15,X$5<=$L15,COUNTIF(휴일!$A$2:$A$20,X$5)=0),IF($G15="선택","□","■"),"") | Y15: =IF(AND(Y$5>=$K15,Y$5<=$L15,COUNTIF(휴일!$A$2:$A$20,Y$5)=0),IF($G15="선택","□","■"),"") | Z15: =IF(AND(Z$5>=$K15,Z$5<=$L15,COUNTIF(휴일!$A$2:$A$20,Z$5)=0),IF($G15="선택","□","■"),"") | AA15: =IF(AND(AA$5>=$K15,AA$5<=$L15,COUNTIF(휴일!$A$2:$A$20,AA$5)=0),IF($G15="선택","□","■"),"") | AB15: =IF(AND(AB$5>=$K15,AB$5<=$L15,COUNTIF(휴일!$A$2:$A$20,AB$5)=0),IF($G15="선택","□","■"),"") | AC15: =IF(AND(AC$5>=$K15,AC$5<=$L15,COUNTIF(휴일!$A$2:$A$20,AC$5)=0),IF($G15="선택","□","■"),"") | AD15: =IF(AND(AD$5>=$K15,AD$5<=$L15,COUNTIF(휴일!$A$2:$A$20,AD$5)=0),IF($G15="선택","□","■"),"") | ... AF15: =IF(AND(AF$5>=$K15,AF$5<=$L15,COUNTIF(휴일!$A$2:$A$20,AF$5)=0),IF($G15="선택","□","■"),"")
E16: FR-15~FR-17 | F16: 출하 차량 모델 준비 | G16: 필수 | H16: 이영노 | I16: 차량 Prefab | J16: 적재함에 파레트 10개를 2열로 놓을 수 있음 | K16: 46322 | L16: 46322 | M16: 46322 | O16: =IF(OR(K16="",L16=""),0,L16-K16+1-COUNTIFS(휴일!$A$2:$A$20,">="&K16,휴일!$A$2:$A$20,"<="&L16)) -> 1 | P16: =IF(OR(M16="",N16=""),0,N16-M16+1-COUNTIFS(휴일!$A$2:$A$20,">="&M16,휴일!$A$2:$A$20,"<="&N16)) -> 0 | Q16: =IF(O16=0,0,MAX(0,MIN(O16,$L$1-K16+1-COUNTIFS(휴일!$A$2:$A$20,">="&K16,휴일!$A$2:$A$20,"<="&$L$1)))) -> 1 | R16: =IF(P16=0,0,MIN(P16,O16)) -> 0 | S16: =IFERROR(Q16/O16,0) -> 1 | T16: =IFERROR(R16/O16,0) -> 0 | U16: =IF(OR(O16=0,R16=0),0,MIN(1,R16/O16)) -> 0 | V16: =U16-S16 -> -1 | W16: =IF(AND(W$5>=$K16,W$5<=$L16,COUNTIF(휴일!$A$2:$A$20,W$5)=0),IF($G16="선택","□","■"),"") -> ■ | X16: =IF(AND(X$5>=$K16,X$5<=$L16,COUNTIF(휴일!$A$2:$A$20,X$5)=0),IF($G16="선택","□","■"),"") | Y16: =IF(AND(Y$5>=$K16,Y$5<=$L16,COUNTIF(휴일!$A$2:$A$20,Y$5)=0),IF($G16="선택","□","■"),"") | Z16: =IF(AND(Z$5>=$K16,Z$5<=$L16,COUNTIF(휴일!$A$2:$A$20,Z$5)=0),IF($G16="선택","□","■"),"") | AA16: =IF(AND(AA$5>=$K16,AA$5<=$L16,COUNTIF(휴일!$A$2:$A$20,AA$5)=0),IF($G16="선택","□","■"),"") | AB16: =IF(AND(AB$5>=$K16,AB$5<=$L16,COUNTIF(휴일!$A$2:$A$20,AB$5)=0),IF($G16="선택","□","■"),"") | AC16: =IF(AND(AC$5>=$K16,AC$5<=$L16,COUNTIF(휴일!$A$2:$A$20,AC$5)=0),IF($G16="선택","□","■"),"") | AD16: =IF(AND(AD$5>=$K16,AD$5<=$L16,COUNTIF(휴일!$A$2:$A$20,AD$5)=0),IF($G16="선택","□","■"),"") | ... AF16: =IF(AND(AF$5>=$K16,AF$5<=$L16,COUNTIF(휴일!$A$2:$A$20,AF$5)=0),IF($G16="선택","□","■"),"")
E17: FR-06 | F17: Code 128 라벨 이미지 준비 | G17: 필수 | H17: 이영노 | I17: 라벨 이미지 3종 | J17: L01, L02, L03 라벨 이미지 생성 | K17: 46322 | L17: 46322 | M17: 46322 | N17: 46322 | O17: =IF(OR(K17="",L17=""),0,L17-K17+1-COUNTIFS(휴일!$A$2:$A$20,">="&K17,휴일!$A$2:$A$20,"<="&L17)) -> 1 | P17: =IF(OR(M17="",N17=""),0,N17-M17+1-COUNTIFS(휴일!$A$2:$A$20,">="&M17,휴일!$A$2:$A$20,"<="&N17)) -> 1 | Q17: =IF(O17=0,0,MAX(0,MIN(O17,$L$1-K17+1-COUNTIFS(휴일!$A$2:$A$20,">="&K17,휴일!$A$2:$A$20,"<="&$L$1)))) -> 1 | R17: =IF(P17=0,0,MIN(P17,O17)) -> 1 | S17: =IFERROR(Q17/O17,0) -> 1 | T17: =IFERROR(R17/O17,0) -> 1 | U17: =IF(OR(O17=0,R17=0),0,MIN(1,R17/O17)) -> 1 | V17: =U17-S17 -> 0 | W17: =IF(AND(W$5>=$K17,W$5<=$L17,COUNTIF(휴일!$A$2:$A$20,W$5)=0),IF($G17="선택","□","■"),"") -> ■ | X17: =IF(AND(X$5>=$K17,X$5<=$L17,COUNTIF(휴일!$A$2:$A$20,X$5)=0),IF($G17="선택","□","■"),"") | Y17: =IF(AND(Y$5>=$K17,Y$5<=$L17,COUNTIF(휴일!$A$2:$A$20,Y$5)=0),IF($G17="선택","□","■"),"") | Z17: =IF(AND(Z$5>=$K17,Z$5<=$L17,COUNTIF(휴일!$A$2:$A$20,Z$5)=0),IF($G17="선택","□","■"),"") | AA17: =IF(AND(AA$5>=$K17,AA$5<=$L17,COUNTIF(휴일!$A$2:$A$20,AA$5)=0),IF($G17="선택","□","■"),"") | AB17: =IF(AND(AB$5>=$K17,AB$5<=$L17,COUNTIF(휴일!$A$2:$A$20,AB$5)=0),IF($G17="선택","□","■"),"") | AC17: =IF(AND(AC$5>=$K17,AC$5<=$L17,COUNTIF(휴일!$A$2:$A$20,AC$5)=0),IF($G17="선택","□","■"),"") | AD17: =IF(AND(AD$5>=$K17,AD$5<=$L17,COUNTIF(휴일!$A$2:$A$20,AD$5)=0),IF($G17="선택","□","■"),"") | ... AF17: =IF(AND(AF$5>=$K17,AF$5<=$L17,COUNTIF(휴일!$A$2:$A$20,AF$5)=0),IF($G17="선택","□","■"),"")
E18: FR-06 | F18: ZXing.Net 패키지 Import | G18: 필수 | H18: 이영노 | I18: ZXing.Net | J18: Unity에서 컴파일 오류 없이 참조됨 | K18: 46322 | L18: 46322 | M18: 46322 | N18: 46322 | O18: =IF(OR(K18="",L18=""),0,L18-K18+1-COUNTIFS(휴일!$A$2:$A$20,">="&K18,휴일!$A$2:$A$20,"<="&L18)) -> 1 | P18: =IF(OR(M18="",N18=""),0,N18-M18+1-COUNTIFS(휴일!$A$2:$A$20,">="&M18,휴일!$A$2:$A$20,"<="&N18)) -> 1 | Q18: =IF(O18=0,0,MAX(0,MIN(O18,$L$1-K18+1-COUNTIFS(휴일!$A$2:$A$20,">="&K18,휴일!$A$2:$A$20,"<="&$L$1)))) -> 1 | R18: =IF(P18=0,0,MIN(P18,O18)) -> 1 | S18: =IFERROR(Q18/O18,0) -> 1 | T18: =IFERROR(R18/O18,0) -> 1 | U18: =IF(OR(O18=0,R18=0),0,MIN(1,R18/O18)) -> 1 | V18: =U18-S18 -> 0 | W18: =IF(AND(W$5>=$K18,W$5<=$L18,COUNTIF(휴일!$A$2:$A$20,W$5)=0),IF($G18="선택","□","■"),"") -> ■ | X18: =IF(AND(X$5>=$K18,X$5<=$L18,COUNTIF(휴일!$A$2:$A$20,X$5)=0),IF($G18="선택","□","■"),"") | Y18: =IF(AND(Y$5>=$K18,Y$5<=$L18,COUNTIF(휴일!$A$2:$A$20,Y$5)=0),IF($G18="선택","□","■"),"") | Z18: =IF(AND(Z$5>=$K18,Z$5<=$L18,COUNTIF(휴일!$A$2:$A$20,Z$5)=0),IF($G18="선택","□","■"),"") | AA18: =IF(AND(AA$5>=$K18,AA$5<=$L18,COUNTIF(휴일!$A$2:$A$20,AA$5)=0),IF($G18="선택","□","■"),"") | AB18: =IF(AND(AB$5>=$K18,AB$5<=$L18,COUNTIF(휴일!$A$2:$A$20,AB$5)=0),IF($G18="선택","□","■"),"") | AC18: =IF(AND(AC$5>=$K18,AC$5<=$L18,COUNTIF(휴일!$A$2:$A$20,AC$5)=0),IF($G18="선택","□","■"),"") | AD18: =IF(AND(AD$5>=$K18,AD$5<=$L18,COUNTIF(휴일!$A$2:$A$20,AD$5)=0),IF($G18="선택","□","■"),"") | ... AF18: =IF(AND(AF$5>=$K18,AF$5<=$L18,COUNTIF(휴일!$A$2:$A$20,AF$5)=0),IF($G18="선택","□","■"),"")
B20: 2 | C20: 0.2 | D20: 씬 구성 | E20: FR-01 | F20: 물류센터 건물 외벽과 바닥 배치 | G20: 필수 | H20: 이영노 | I20: LogisticsCenter 씬 | J20: 건물 외벽과 바닥이 배치되고 내부에 4개 구역 공간이 확보됨 | K20: 46323 | L20: 46323 | O20: =IF(OR(K20="",L20=""),0,L20-K20+1-COUNTIFS(휴일!$A$2:$A$20,">="&K20,휴일!$A$2:$A$20,"<="&L20)) -> 1 | P20: =IF(OR(M20="",N20=""),0,N20-M20+1-COUNTIFS(휴일!$A$2:$A$20,">="&M20,휴일!$A$2:$A$20,"<="&N20)) -> 0 | Q20: =IF(O20=0,0,MAX(0,MIN(O20,$L$1-K20+1-COUNTIFS(휴일!$A$2:$A$20,">="&K20,휴일!$A$2:$A$20,"<="&$L$1)))) -> 0 | R20: =IF(P20=0,0,MIN(P20,O20)) -> 0 | S20: =IFERROR(Q20/O20,0) -> 0 | T20: =IFERROR(R20/O20,0) -> 0 | U20: =IF(OR(O20=0,R20=0),0,MIN(1,R20/O20)) -> 0 | V20: =U20-S20 -> 0 | W20: =IF(AND(W$5>=$K20,W$5<=$L20,COUNTIF(휴일!$A$2:$A$20,W$5)=0),IF($G20="선택","□","■"),"") | X20: =IF(AND(X$5>=$K20,X$5<=$L20,COUNTIF(휴일!$A$2:$A$20,X$5)=0),IF($G20="선택","□","■"),"") -> ■ | Y20: =IF(AND(Y$5>=$K20,Y$5<=$L20,COUNTIF(휴일!$A$2:$A$20,Y$5)=0),IF($G20="선택","□","■"),"") | Z20: =IF(AND(Z$5>=$K20,Z$5<=$L20,COUNTIF(휴일!$A$2:$A$20,Z$5)=0),IF($G20="선택","□","■"),"") | AA20: =IF(AND(AA$5>=$K20,AA$5<=$L20,COUNTIF(휴일!$A$2:$A$20,AA$5)=0),IF($G20="선택","□","■"),"") | AB20: =IF(AND(AB$5>=$K20,AB$5<=$L20,COUNTIF(휴일!$A$2:$A$20,AB$5)=0),IF($G20="선택","□","■"),"") | AC20: =IF(AND(AC$5>=$K20,AC$5<=$L20,COUNTIF(휴일!$A$2:$A$20,AC$5)=0),IF($G20="선택","□","■"),"") | AD20: =IF(AND(AD$5>=$K20,AD$5<=$L20,COUNTIF(휴일!$A$2:$A$20,AD$5)=0),IF($G20="선택","□","■"),"") | ... AF20: =IF(AND(AF$5>=$K20,AF$5<=$L20,COUNTIF(휴일!$A$2:$A$20,AF$5)=0),IF($G20="선택","□","■"),"")
E21: FR-01 | F21: 투입 구역 배치 | G21: 필수 | H21: 이영노 | I21: 투입 구역 | J21: 투입 구역 경계와 박스 투입 위치가 표시됨 | K21: 46323 | L21: 46323 | O21: =IF(OR(K21="",L21=""),0,L21-K21+1-COUNTIFS(휴일!$A$2:$A$20,">="&K21,휴일!$A$2:$A$20,"<="&L21)) -> 1 | P21: =IF(OR(M21="",N21=""),0,N21-M21+1-COUNTIFS(휴일!$A$2:$A$20,">="&M21,휴일!$A$2:$A$20,"<="&N21)) -> 0 | Q21: =IF(O21=0,0,MAX(0,MIN(O21,$L$1-K21+1-COUNTIFS(휴일!$A$2:$A$20,">="&K21,휴일!$A$2:$A$20,"<="&$L$1)))) -> 0 | R21: =IF(P21=0,0,MIN(P21,O21)) -> 0 | S21: =IFERROR(Q21/O21,0) -> 0 | T21: =IFERROR(R21/O21,0) -> 0 | U21: =IF(OR(O21=0,R21=0),0,MIN(1,R21/O21)) -> 0 | V21: =U21-S21 -> 0 | W21: =IF(AND(W$5>=$K21,W$5<=$L21,COUNTIF(휴일!$A$2:$A$20,W$5)=0),IF($G21="선택","□","■"),"") | X21: =IF(AND(X$5>=$K21,X$5<=$L21,COUNTIF(휴일!$A$2:$A$20,X$5)=0),IF($G21="선택","□","■"),"") -> ■ | Y21: =IF(AND(Y$5>=$K21,Y$5<=$L21,COUNTIF(휴일!$A$2:$A$20,Y$5)=0),IF($G21="선택","□","■"),"") | Z21: =IF(AND(Z$5>=$K21,Z$5<=$L21,COUNTIF(휴일!$A$2:$A$20,Z$5)=0),IF($G21="선택","□","■"),"") | AA21: =IF(AND(AA$5>=$K21,AA$5<=$L21,COUNTIF(휴일!$A$2:$A$20,AA$5)=0),IF($G21="선택","□","■"),"") | AB21: =IF(AND(AB$5>=$K21,AB$5<=$L21,COUNTIF(휴일!$A$2:$A$20,AB$5)=0),IF($G21="선택","□","■"),"") | AC21: =IF(AND(AC$5>=$K21,AC$5<=$L21,COUNTIF(휴일!$A$2:$A$20,AC$5)=0),IF($G21="선택","□","■"),"") | AD21: =IF(AND(AD$5>=$K21,AD$5<=$L21,COUNTIF(휴일!$A$2:$A$20,AD$5)=0),IF($G21="선택","□","■"),"") | ... AF21: =IF(AND(AF$5>=$K21,AF$5<=$L21,COUNTIF(휴일!$A$2:$A$20,AF$5)=0),IF($G21="선택","□","■"),"")
E22: FR-01 | F22: 분류 구역 배치 | G22: 필수 | H22: 이영노 | I22: 분류 구역 | J22: 분류 구역 경계와 바코드 판독 위치가 표시됨 | K22: 46323 | L22: 46323 | O22: =IF(OR(K22="",L22=""),0,L22-K22+1-COUNTIFS(휴일!$A$2:$A$20,">="&K22,휴일!$A$2:$A$20,"<="&L22)) -> 1 | P22: =IF(OR(M22="",N22=""),0,N22-M22+1-COUNTIFS(휴일!$A$2:$A$20,">="&M22,휴일!$A$2:$A$20,"<="&N22)) -> 0 | Q22: =IF(O22=0,0,MAX(0,MIN(O22,$L$1-K22+1-COUNTIFS(휴일!$A$2:$A$20,">="&K22,휴일!$A$2:$A$20,"<="&$L$1)))) -> 0 | R22: =IF(P22=0,0,MIN(P22,O22)) -> 0 | S22: =IFERROR(Q22/O22,0) -> 0 | T22: =IFERROR(R22/O22,0) -> 0 | U22: =IF(OR(O22=0,R22=0),0,MIN(1,R22/O22)) -> 0 | V22: =U22-S22 -> 0 | W22: =IF(AND(W$5>=$K22,W$5<=$L22,COUNTIF(휴일!$A$2:$A$20,W$5)=0),IF($G22="선택","□","■"),"") | X22: =IF(AND(X$5>=$K22,X$5<=$L22,COUNTIF(휴일!$A$2:$A$20,X$5)=0),IF($G22="선택","□","■"),"") -> ■ | Y22: =IF(AND(Y$5>=$K22,Y$5<=$L22,COUNTIF(휴일!$A$2:$A$20,Y$5)=0),IF($G22="선택","□","■"),"") | Z22: =IF(AND(Z$5>=$K22,Z$5<=$L22,COUNTIF(휴일!$A$2:$A$20,Z$5)=0),IF($G22="선택","□","■"),"") | AA22: =IF(AND(AA$5>=$K22,AA$5<=$L22,COUNTIF(휴일!$A$2:$A$20,AA$5)=0),IF($G22="선택","□","■"),"") | AB22: =IF(AND(AB$5>=$K22,AB$5<=$L22,COUNTIF(휴일!$A$2:$A$20,AB$5)=0),IF($G22="선택","□","■"),"") | AC22: =IF(AND(AC$5>=$K22,AC$5<=$L22,COUNTIF(휴일!$A$2:$A$20,AC$5)=0),IF($G22="선택","□","■"),"") | AD22: =IF(AND(AD$5>=$K22,AD$5<=$L22,COUNTIF(휴일!$A$2:$A$20,AD$5)=0),IF($G22="선택","□","■"),"") | ... AF22: =IF(AND(AF$5>=$K22,AF$5<=$L22,COUNTIF(휴일!$A$2:$A$20,AF$5)=0),IF($G22="선택","□","■"),"")
E23: FR-01 | F23: 파레타이징 구역 배치 | G23: 필수 | H23: 이영노 | I23: 파레타이징 구역 | J23: 레인 3개에 대응하는 FR5 셀 3곳의 공간이 확보됨 | K23: 46323 | L23: 46323 | O23: =IF(OR(K23="",L23=""),0,L23-K23+1-COUNTIFS(휴일!$A$2:$A$20,">="&K23,휴일!$A$2:$A$20,"<="&L23)) -> 1 | P23: =IF(OR(M23="",N23=""),0,N23-M23+1-COUNTIFS(휴일!$A$2:$A$20,">="&M23,휴일!$A$2:$A$20,"<="&N23)) -> 0 | Q23: =IF(O23=0,0,MAX(0,MIN(O23,$L$1-K23+1-COUNTIFS(휴일!$A$2:$A$20,">="&K23,휴일!$A$2:$A$20,"<="&$L$1)))) -> 0 | R23: =IF(P23=0,0,MIN(P23,O23)) -> 0 | S23: =IFERROR(Q23/O23,0) -> 0 | T23: =IFERROR(R23/O23,0) -> 0 | U23: =IF(OR(O23=0,R23=0),0,MIN(1,R23/O23)) -> 0 | V23: =U23-S23 -> 0 | W23: =IF(AND(W$5>=$K23,W$5<=$L23,COUNTIF(휴일!$A$2:$A$20,W$5)=0),IF($G23="선택","□","■"),"") | X23: =IF(AND(X$5>=$K23,X$5<=$L23,COUNTIF(휴일!$A$2:$A$20,X$5)=0),IF($G23="선택","□","■"),"") -> ■ | Y23: =IF(AND(Y$5>=$K23,Y$5<=$L23,COUNTIF(휴일!$A$2:$A$20,Y$5)=0),IF($G23="선택","□","■"),"") | Z23: =IF(AND(Z$5>=$K23,Z$5<=$L23,COUNTIF(휴일!$A$2:$A$20,Z$5)=0),IF($G23="선택","□","■"),"") | AA23: =IF(AND(AA$5>=$K23,AA$5<=$L23,COUNTIF(휴일!$A$2:$A$20,AA$5)=0),IF($G23="선택","□","■"),"") | AB23: =IF(AND(AB$5>=$K23,AB$5<=$L23,COUNTIF(휴일!$A$2:$A$20,AB$5)=0),IF($G23="선택","□","■"),"") | AC23: =IF(AND(AC$5>=$K23,AC$5<=$L23,COUNTIF(휴일!$A$2:$A$20,AC$5)=0),IF($G23="선택","□","■"),"") | AD23: =IF(AND(AD$5>=$K23,AD$5<=$L23,COUNTIF(휴일!$A$2:$A$20,AD$5)=0),IF($G23="선택","□","■"),"") | ... AF23: =IF(AND(AF$5>=$K23,AF$5<=$L23,COUNTIF(휴일!$A$2:$A$20,AF$5)=0),IF($G23="선택","□","■"),"")
E24: FR-01 | F24: 출하 도크 구역 배치 | G24: 필수 | H24: 이영노 | I24: 출하 도크 구역 | J24: 도크 3개 위치와 차량 대기 공간이 확보됨 | K24: 46323 | L24: 46323 | O24: =IF(OR(K24="",L24=""),0,L24-K24+1-COUNTIFS(휴일!$A$2:$A$20,">="&K24,휴일!$A$2:$A$20,"<="&L24)) -> 1 | P24: =IF(OR(M24="",N24=""),0,N24-M24+1-COUNTIFS(휴일!$A$2:$A$20,">="&M24,휴일!$A$2:$A$20,"<="&N24)) -> 0 | Q24: =IF(O24=0,0,MAX(0,MIN(O24,$L$1-K24+1-COUNTIFS(휴일!$A$2:$A$20,">="&K24,휴일!$A$2:$A$20,"<="&$L$1)))) -> 0 | R24: =IF(P24=0,0,MIN(P24,O24)) -> 0 | S24: =IFERROR(Q24/O24,0) -> 0 | T24: =IFERROR(R24/O24,0) -> 0 | U24: =IF(OR(O24=0,R24=0),0,MIN(1,R24/O24)) -> 0 | V24: =U24-S24 -> 0 | W24: =IF(AND(W$5>=$K24,W$5<=$L24,COUNTIF(휴일!$A$2:$A$20,W$5)=0),IF($G24="선택","□","■"),"") | X24: =IF(AND(X$5>=$K24,X$5<=$L24,COUNTIF(휴일!$A$2:$A$20,X$5)=0),IF($G24="선택","□","■"),"") -> ■ | Y24: =IF(AND(Y$5>=$K24,Y$5<=$L24,COUNTIF(휴일!$A$2:$A$20,Y$5)=0),IF($G24="선택","□","■"),"") | Z24: =IF(AND(Z$5>=$K24,Z$5<=$L24,COUNTIF(휴일!$A$2:$A$20,Z$5)=0),IF($G24="선택","□","■"),"") | AA24: =IF(AND(AA$5>=$K24,AA$5<=$L24,COUNTIF(휴일!$A$2:$A$20,AA$5)=0),IF($G24="선택","□","■"),"") | AB24: =IF(AND(AB$5>=$K24,AB$5<=$L24,COUNTIF(휴일!$A$2:$A$20,AB$5)=0),IF($G24="선택","□","■"),"") | AC24: =IF(AND(AC$5>=$K24,AC$5<=$L24,COUNTIF(휴일!$A$2:$A$20,AC$5)=0),IF($G24="선택","□","■"),"") | AD24: =IF(AND(AD$5>=$K24,AD$5<=$L24,COUNTIF(휴일!$A$2:$A$20,AD$5)=0),IF($G24="선택","□","■"),"") | ... AF24: =IF(AND(AF$5>=$K24,AF$5<=$L24,COUNTIF(휴일!$A$2:$A$20,AF$5)=0),IF($G24="선택","□","■"),"")
E25: FR-01, FR-05 | F25: 순환 메인 컨베이어 배치 | G25: 필수 | H25: 이영노 | I25: 컨베이어 배치 | J25: 투입 위치에서 시작하는 순환 경로가 끊김 없이 연결됨 | K25: 46323 | L25: 46323 | O25: =IF(OR(K25="",L25=""),0,L25-K25+1-COUNTIFS(휴일!$A$2:$A$20,">="&K25,휴일!$A$2:$A$20,"<="&L25)) -> 1 | P25: =IF(OR(M25="",N25=""),0,N25-M25+1-COUNTIFS(휴일!$A$2:$A$20,">="&M25,휴일!$A$2:$A$20,"<="&N25)) -> 0 | Q25: =IF(O25=0,0,MAX(0,MIN(O25,$L$1-K25+1-COUNTIFS(휴일!$A$2:$A$20,">="&K25,휴일!$A$2:$A$20,"<="&$L$1)))) -> 0 | R25: =IF(P25=0,0,MIN(P25,O25)) -> 0 | S25: =IFERROR(Q25/O25,0) -> 0 | T25: =IFERROR(R25/O25,0) -> 0 | U25: =IF(OR(O25=0,R25=0),0,MIN(1,R25/O25)) -> 0 | V25: =U25-S25 -> 0 | W25: =IF(AND(W$5>=$K25,W$5<=$L25,COUNTIF(휴일!$A$2:$A$20,W$5)=0),IF($G25="선택","□","■"),"") | X25: =IF(AND(X$5>=$K25,X$5<=$L25,COUNTIF(휴일!$A$2:$A$20,X$5)=0),IF($G25="선택","□","■"),"") -> ■ | Y25: =IF(AND(Y$5>=$K25,Y$5<=$L25,COUNTIF(휴일!$A$2:$A$20,Y$5)=0),IF($G25="선택","□","■"),"") | Z25: =IF(AND(Z$5>=$K25,Z$5<=$L25,COUNTIF(휴일!$A$2:$A$20,Z$5)=0),IF($G25="선택","□","■"),"") | AA25: =IF(AND(AA$5>=$K25,AA$5<=$L25,COUNTIF(휴일!$A$2:$A$20,AA$5)=0),IF($G25="선택","□","■"),"") | AB25: =IF(AND(AB$5>=$K25,AB$5<=$L25,COUNTIF(휴일!$A$2:$A$20,AB$5)=0),IF($G25="선택","□","■"),"") | AC25: =IF(AND(AC$5>=$K25,AC$5<=$L25,COUNTIF(휴일!$A$2:$A$20,AC$5)=0),IF($G25="선택","□","■"),"") | AD25: =IF(AND(AD$5>=$K25,AD$5<=$L25,COUNTIF(휴일!$A$2:$A$20,AD$5)=0),IF($G25="선택","□","■"),"") | ... AF25: =IF(AND(AF$5>=$K25,AF$5<=$L25,COUNTIF(휴일!$A$2:$A$20,AF$5)=0),IF($G25="선택","□","■"),"")
E26: FR-01, FR-07 | F26: 레인 분기 장치 3개 배치 | G26: 필수 | H26: 이영노 | I26: 분기 장치 배치 | J26: 메인 컨베이어 위 레인 1~3 분기점에 설치됨 | K26: 46323 | L26: 46323 | O26: =IF(OR(K26="",L26=""),0,L26-K26+1-COUNTIFS(휴일!$A$2:$A$20,">="&K26,휴일!$A$2:$A$20,"<="&L26)) -> 1 | P26: =IF(OR(M26="",N26=""),0,N26-M26+1-COUNTIFS(휴일!$A$2:$A$20,">="&M26,휴일!$A$2:$A$20,"<="&N26)) -> 0 | Q26: =IF(O26=0,0,MAX(0,MIN(O26,$L$1-K26+1-COUNTIFS(휴일!$A$2:$A$20,">="&K26,휴일!$A$2:$A$20,"<="&$L$1)))) -> 0 | R26: =IF(P26=0,0,MIN(P26,O26)) -> 0 | S26: =IFERROR(Q26/O26,0) -> 0 | T26: =IFERROR(R26/O26,0) -> 0 | U26: =IF(OR(O26=0,R26=0),0,MIN(1,R26/O26)) -> 0 | V26: =U26-S26 -> 0 | W26: =IF(AND(W$5>=$K26,W$5<=$L26,COUNTIF(휴일!$A$2:$A$20,W$5)=0),IF($G26="선택","□","■"),"") | X26: =IF(AND(X$5>=$K26,X$5<=$L26,COUNTIF(휴일!$A$2:$A$20,X$5)=0),IF($G26="선택","□","■"),"") -> ■ | Y26: =IF(AND(Y$5>=$K26,Y$5<=$L26,COUNTIF(휴일!$A$2:$A$20,Y$5)=0),IF($G26="선택","□","■"),"") | Z26: =IF(AND(Z$5>=$K26,Z$5<=$L26,COUNTIF(휴일!$A$2:$A$20,Z$5)=0),IF($G26="선택","□","■"),"") | AA26: =IF(AND(AA$5>=$K26,AA$5<=$L26,COUNTIF(휴일!$A$2:$A$20,AA$5)=0),IF($G26="선택","□","■"),"") | AB26: =IF(AND(AB$5>=$K26,AB$5<=$L26,COUNTIF(휴일!$A$2:$A$20,AB$5)=0),IF($G26="선택","□","■"),"") | AC26: =IF(AND(AC$5>=$K26,AC$5<=$L26,COUNTIF(휴일!$A$2:$A$20,AC$5)=0),IF($G26="선택","□","■"),"") | AD26: =IF(AND(AD$5>=$K26,AD$5<=$L26,COUNTIF(휴일!$A$2:$A$20,AD$5)=0),IF($G26="선택","□","■"),"") | ... AF26: =IF(AND(AF$5>=$K26,AF$5<=$L26,COUNTIF(휴일!$A$2:$A$20,AF$5)=0),IF($G26="선택","□","■"),"")
E27: FR-01, FR-08 | F27: 경사 롤러 레인 3개 배치 | G27: 필수 | H27: 이영노 | I27: 레인 배치 | J27: 레인 3개가 분기점에서 픽업 구역까지 연결됨 | K27: 46323 | L27: 46323 | O27: =IF(OR(K27="",L27=""),0,L27-K27+1-COUNTIFS(휴일!$A$2:$A$20,">="&K27,휴일!$A$2:$A$20,"<="&L27)) -> 1 | P27: =IF(OR(M27="",N27=""),0,N27-M27+1-COUNTIFS(휴일!$A$2:$A$20,">="&M27,휴일!$A$2:$A$20,"<="&N27)) -> 0 | Q27: =IF(O27=0,0,MAX(0,MIN(O27,$L$1-K27+1-COUNTIFS(휴일!$A$2:$A$20,">="&K27,휴일!$A$2:$A$20,"<="&$L$1)))) -> 0 | R27: =IF(P27=0,0,MIN(P27,O27)) -> 0 | S27: =IFERROR(Q27/O27,0) -> 0 | T27: =IFERROR(R27/O27,0) -> 0 | U27: =IF(OR(O27=0,R27=0),0,MIN(1,R27/O27)) -> 0 | V27: =U27-S27 -> 0 | W27: =IF(AND(W$5>=$K27,W$5<=$L27,COUNTIF(휴일!$A$2:$A$20,W$5)=0),IF($G27="선택","□","■"),"") | X27: =IF(AND(X$5>=$K27,X$5<=$L27,COUNTIF(휴일!$A$2:$A$20,X$5)=0),IF($G27="선택","□","■"),"") -> ■ | Y27: =IF(AND(Y$5>=$K27,Y$5<=$L27,COUNTIF(휴일!$A$2:$A$20,Y$5)=0),IF($G27="선택","□","■"),"") | Z27: =IF(AND(Z$5>=$K27,Z$5<=$L27,COUNTIF(휴일!$A$2:$A$20,Z$5)=0),IF($G27="선택","□","■"),"") | AA27: =IF(AND(AA$5>=$K27,AA$5<=$L27,COUNTIF(휴일!$A$2:$A$20,AA$5)=0),IF($G27="선택","□","■"),"") | AB27: =IF(AND(AB$5>=$K27,AB$5<=$L27,COUNTIF(휴일!$A$2:$A$20,AB$5)=0),IF($G27="선택","□","■"),"") | AC27: =IF(AND(AC$5>=$K27,AC$5<=$L27,COUNTIF(휴일!$A$2:$A$20,AC$5)=0),IF($G27="선택","□","■"),"") | AD27: =IF(AND(AD$5>=$K27,AD$5<=$L27,COUNTIF(휴일!$A$2:$A$20,AD$5)=0),IF($G27="선택","□","■"),"") | ... AF27: =IF(AND(AF$5>=$K27,AF$5<=$L27,COUNTIF(휴일!$A$2:$A$20,AF$5)=0),IF($G27="선택","□","■"),"")
E28: FR-01, FR-19 | F28: 레인별 중간 대기 스토퍼 배치 | G28: 필수 | H28: 이영노 | I28: 중간 스토퍼 배치 | J28: 레인마다 픽업 구역 앞에 1개 설치됨 | K28: 46324 | L28: 46324 | O28: =IF(OR(K28="",L28=""),0,L28-K28+1-COUNTIFS(휴일!$A$2:$A$20,">="&K28,휴일!$A$2:$A$20,"<="&L28)) -> 1 | P28: =IF(OR(M28="",N28=""),0,N28-M28+1-COUNTIFS(휴일!$A$2:$A$20,">="&M28,휴일!$A$2:$A$20,"<="&N28)) -> 0 | Q28: =IF(O28=0,0,MAX(0,MIN(O28,$L$1-K28+1-COUNTIFS(휴일!$A$2:$A$20,">="&K28,휴일!$A$2:$A$20,"<="&$L$1)))) -> 0 | R28: =IF(P28=0,0,MIN(P28,O28)) -> 0 | S28: =IFERROR(Q28/O28,0) -> 0 | T28: =IFERROR(R28/O28,0) -> 0 | U28: =IF(OR(O28=0,R28=0),0,MIN(1,R28/O28)) -> 0 | V28: =U28-S28 -> 0 | W28: =IF(AND(W$5>=$K28,W$5<=$L28,COUNTIF(휴일!$A$2:$A$20,W$5)=0),IF($G28="선택","□","■"),"") | X28: =IF(AND(X$5>=$K28,X$5<=$L28,COUNTIF(휴일!$A$2:$A$20,X$5)=0),IF($G28="선택","□","■"),"") | Y28: =IF(AND(Y$5>=$K28,Y$5<=$L28,COUNTIF(휴일!$A$2:$A$20,Y$5)=0),IF($G28="선택","□","■"),"") -> ■ | Z28: =IF(AND(Z$5>=$K28,Z$5<=$L28,COUNTIF(휴일!$A$2:$A$20,Z$5)=0),IF($G28="선택","□","■"),"") | AA28: =IF(AND(AA$5>=$K28,AA$5<=$L28,COUNTIF(휴일!$A$2:$A$20,AA$5)=0),IF($G28="선택","□","■"),"") | AB28: =IF(AND(AB$5>=$K28,AB$5<=$L28,COUNTIF(휴일!$A$2:$A$20,AB$5)=0),IF($G28="선택","□","■"),"") | AC28: =IF(AND(AC$5>=$K28,AC$5<=$L28,COUNTIF(휴일!$A$2:$A$20,AC$5)=0),IF($G28="선택","□","■"),"") | AD28: =IF(AND(AD$5>=$K28,AD$5<=$L28,COUNTIF(휴일!$A$2:$A$20,AD$5)=0),IF($G28="선택","□","■"),"") | ... AF28: =IF(AND(AF$5>=$K28,AF$5<=$L28,COUNTIF(휴일!$A$2:$A$20,AF$5)=0),IF($G28="선택","□","■"),"")
E29: FR-01, FR-22 | F29: 레인별 픽업 끝 스토퍼 배치 | G29: 필수 | H29: 이영노 | I29: 끝 스토퍼 배치 | J29: 레인마다 픽업 구역 끝에 중간 스토퍼와 별도로 설치됨 | K29: 46324 | L29: 46324 | O29: =IF(OR(K29="",L29=""),0,L29-K29+1-COUNTIFS(휴일!$A$2:$A$20,">="&K29,휴일!$A$2:$A$20,"<="&L29)) -> 1 | P29: =IF(OR(M29="",N29=""),0,N29-M29+1-COUNTIFS(휴일!$A$2:$A$20,">="&M29,휴일!$A$2:$A$20,"<="&N29)) -> 0 | Q29: =IF(O29=0,0,MAX(0,MIN(O29,$L$1-K29+1-COUNTIFS(휴일!$A$2:$A$20,">="&K29,휴일!$A$2:$A$20,"<="&$L$1)))) -> 0 | R29: =IF(P29=0,0,MIN(P29,O29)) -> 0 | S29: =IFERROR(Q29/O29,0) -> 0 | T29: =IFERROR(R29/O29,0) -> 0 | U29: =IF(OR(O29=0,R29=0),0,MIN(1,R29/O29)) -> 0 | V29: =U29-S29 -> 0 | W29: =IF(AND(W$5>=$K29,W$5<=$L29,COUNTIF(휴일!$A$2:$A$20,W$5)=0),IF($G29="선택","□","■"),"") | X29: =IF(AND(X$5>=$K29,X$5<=$L29,COUNTIF(휴일!$A$2:$A$20,X$5)=0),IF($G29="선택","□","■"),"") | Y29: =IF(AND(Y$5>=$K29,Y$5<=$L29,COUNTIF(휴일!$A$2:$A$20,Y$5)=0),IF($G29="선택","□","■"),"") -> ■ | Z29: =IF(AND(Z$5>=$K29,Z$5<=$L29,COUNTIF(휴일!$A$2:$A$20,Z$5)=0),IF($G29="선택","□","■"),"") | AA29: =IF(AND(AA$5>=$K29,AA$5<=$L29,COUNTIF(휴일!$A$2:$A$20,AA$5)=0),IF($G29="선택","□","■"),"") | AB29: =IF(AND(AB$5>=$K29,AB$5<=$L29,COUNTIF(휴일!$A$2:$A$20,AB$5)=0),IF($G29="선택","□","■"),"") | AC29: =IF(AND(AC$5>=$K29,AC$5<=$L29,COUNTIF(휴일!$A$2:$A$20,AC$5)=0),IF($G29="선택","□","■"),"") | AD29: =IF(AND(AD$5>=$K29,AD$5<=$L29,COUNTIF(휴일!$A$2:$A$20,AD$5)=0),IF($G29="선택","□","■"),"") | ... AF29: =IF(AND(AF$5>=$K29,AF$5<=$L29,COUNTIF(휴일!$A$2:$A$20,AF$5)=0),IF($G29="선택","□","■"),"")
E30: FR-01, FR-22 | F30: 레인별 측면 가이드 배치 | G30: 필수 | H30: 이영노 | I30: 측면 가이드 배치 | J30: 픽업 구역 양쪽에 박스 폭 280mm 기준으로 설치됨 | K30: 46324 | L30: 46324 | O30: =IF(OR(K30="",L30=""),0,L30-K30+1-COUNTIFS(휴일!$A$2:$A$20,">="&K30,휴일!$A$2:$A$20,"<="&L30)) -> 1 | P30: =IF(OR(M30="",N30=""),0,N30-M30+1-COUNTIFS(휴일!$A$2:$A$20,">="&M30,휴일!$A$2:$A$20,"<="&N30)) -> 0 | Q30: =IF(O30=0,0,MAX(0,MIN(O30,$L$1-K30+1-COUNTIFS(휴일!$A$2:$A$20,">="&K30,휴일!$A$2:$A$20,"<="&$L$1)))) -> 0 | R30: =IF(P30=0,0,MIN(P30,O30)) -> 0 | S30: =IFERROR(Q30/O30,0) -> 0 | T30: =IFERROR(R30/O30,0) -> 0 | U30: =IF(OR(O30=0,R30=0),0,MIN(1,R30/O30)) -> 0 | V30: =U30-S30 -> 0 | W30: =IF(AND(W$5>=$K30,W$5<=$L30,COUNTIF(휴일!$A$2:$A$20,W$5)=0),IF($G30="선택","□","■"),"") | X30: =IF(AND(X$5>=$K30,X$5<=$L30,COUNTIF(휴일!$A$2:$A$20,X$5)=0),IF($G30="선택","□","■"),"") | Y30: =IF(AND(Y$5>=$K30,Y$5<=$L30,COUNTIF(휴일!$A$2:$A$20,Y$5)=0),IF($G30="선택","□","■"),"") -> ■ | Z30: =IF(AND(Z$5>=$K30,Z$5<=$L30,COUNTIF(휴일!$A$2:$A$20,Z$5)=0),IF($G30="선택","□","■"),"") | AA30: =IF(AND(AA$5>=$K30,AA$5<=$L30,COUNTIF(휴일!$A$2:$A$20,AA$5)=0),IF($G30="선택","□","■"),"") | AB30: =IF(AND(AB$5>=$K30,AB$5<=$L30,COUNTIF(휴일!$A$2:$A$20,AB$5)=0),IF($G30="선택","□","■"),"") | AC30: =IF(AND(AC$5>=$K30,AC$5<=$L30,COUNTIF(휴일!$A$2:$A$20,AC$5)=0),IF($G30="선택","□","■"),"") | AD30: =IF(AND(AD$5>=$K30,AD$5<=$L30,COUNTIF(휴일!$A$2:$A$20,AD$5)=0),IF($G30="선택","□","■"),"") | ... AF30: =IF(AND(AF$5>=$K30,AF$5<=$L30,COUNTIF(휴일!$A$2:$A$20,AF$5)=0),IF($G30="선택","□","■"),"")
E31: FR-01, FR-10 | F31: 레인별 FR5 3대 배치 | G31: 필수 | H31: 이영노 | I31: FR5 배치 | J31: 베이스 높이 950mm로 레인마다 1대 설치됨 | K31: 46324 | L31: 46324 | O31: =IF(OR(K31="",L31=""),0,L31-K31+1-COUNTIFS(휴일!$A$2:$A$20,">="&K31,휴일!$A$2:$A$20,"<="&L31)) -> 1 | P31: =IF(OR(M31="",N31=""),0,N31-M31+1-COUNTIFS(휴일!$A$2:$A$20,">="&M31,휴일!$A$2:$A$20,"<="&N31)) -> 0 | Q31: =IF(O31=0,0,MAX(0,MIN(O31,$L$1-K31+1-COUNTIFS(휴일!$A$2:$A$20,">="&K31,휴일!$A$2:$A$20,"<="&$L$1)))) -> 0 | R31: =IF(P31=0,0,MIN(P31,O31)) -> 0 | S31: =IFERROR(Q31/O31,0) -> 0 | T31: =IFERROR(R31/O31,0) -> 0 | U31: =IF(OR(O31=0,R31=0),0,MIN(1,R31/O31)) -> 0 | V31: =U31-S31 -> 0 | W31: =IF(AND(W$5>=$K31,W$5<=$L31,COUNTIF(휴일!$A$2:$A$20,W$5)=0),IF($G31="선택","□","■"),"") | X31: =IF(AND(X$5>=$K31,X$5<=$L31,COUNTIF(휴일!$A$2:$A$20,X$5)=0),IF($G31="선택","□","■"),"") | Y31: =IF(AND(Y$5>=$K31,Y$5<=$L31,COUNTIF(휴일!$A$2:$A$20,Y$5)=0),IF($G31="선택","□","■"),"") -> ■ | Z31: =IF(AND(Z$5>=$K31,Z$5<=$L31,COUNTIF(휴일!$A$2:$A$20,Z$5)=0),IF($G31="선택","□","■"),"") | AA31: =IF(AND(AA$5>=$K31,AA$5<=$L31,COUNTIF(휴일!$A$2:$A$20,AA$5)=0),IF($G31="선택","□","■"),"") | AB31: =IF(AND(AB$5>=$K31,AB$5<=$L31,COUNTIF(휴일!$A$2:$A$20,AB$5)=0),IF($G31="선택","□","■"),"") | AC31: =IF(AND(AC$5>=$K31,AC$5<=$L31,COUNTIF(휴일!$A$2:$A$20,AC$5)=0),IF($G31="선택","□","■"),"") | AD31: =IF(AND(AD$5>=$K31,AD$5<=$L31,COUNTIF(휴일!$A$2:$A$20,AD$5)=0),IF($G31="선택","□","■"),"") | ... AF31: =IF(AND(AF$5>=$K31,AF$5<=$L31,COUNTIF(휴일!$A$2:$A$20,AF$5)=0),IF($G31="선택","□","■"),"")
E32: FR-01, FR-10 | F32: 레인별 파레트 작업 위치 3곳 배치 | G32: 필수 | H32: 이영노 | I32: 파레트 위치 | J32: 로봇 축에서 파레트 가까운 변까지 150mm로 배치 | K32: 46324 | L32: 46324 | O32: =IF(OR(K32="",L32=""),0,L32-K32+1-COUNTIFS(휴일!$A$2:$A$20,">="&K32,휴일!$A$2:$A$20,"<="&L32)) -> 1 | P32: =IF(OR(M32="",N32=""),0,N32-M32+1-COUNTIFS(휴일!$A$2:$A$20,">="&M32,휴일!$A$2:$A$20,"<="&N32)) -> 0 | Q32: =IF(O32=0,0,MAX(0,MIN(O32,$L$1-K32+1-COUNTIFS(휴일!$A$2:$A$20,">="&K32,휴일!$A$2:$A$20,"<="&$L$1)))) -> 0 | R32: =IF(P32=0,0,MIN(P32,O32)) -> 0 | S32: =IFERROR(Q32/O32,0) -> 0 | T32: =IFERROR(R32/O32,0) -> 0 | U32: =IF(OR(O32=0,R32=0),0,MIN(1,R32/O32)) -> 0 | V32: =U32-S32 -> 0 | W32: =IF(AND(W$5>=$K32,W$5<=$L32,COUNTIF(휴일!$A$2:$A$20,W$5)=0),IF($G32="선택","□","■"),"") | X32: =IF(AND(X$5>=$K32,X$5<=$L32,COUNTIF(휴일!$A$2:$A$20,X$5)=0),IF($G32="선택","□","■"),"") | Y32: =IF(AND(Y$5>=$K32,Y$5<=$L32,COUNTIF(휴일!$A$2:$A$20,Y$5)=0),IF($G32="선택","□","■"),"") -> ■ | Z32: =IF(AND(Z$5>=$K32,Z$5<=$L32,COUNTIF(휴일!$A$2:$A$20,Z$5)=0),IF($G32="선택","□","■"),"") | AA32: =IF(AND(AA$5>=$K32,AA$5<=$L32,COUNTIF(휴일!$A$2:$A$20,AA$5)=0),IF($G32="선택","□","■"),"") | AB32: =IF(AND(AB$5>=$K32,AB$5<=$L32,COUNTIF(휴일!$A$2:$A$20,AB$5)=0),IF($G32="선택","□","■"),"") | AC32: =IF(AND(AC$5>=$K32,AC$5<=$L32,COUNTIF(휴일!$A$2:$A$20,AC$5)=0),IF($G32="선택","□","■"),"") | AD32: =IF(AND(AD$5>=$K32,AD$5<=$L32,COUNTIF(휴일!$A$2:$A$20,AD$5)=0),IF($G32="선택","□","■"),"") | ... AF32: =IF(AND(AF$5>=$K32,AF$5<=$L32,COUNTIF(휴일!$A$2:$A$20,AF$5)=0),IF($G32="선택","□","■"),"")
... E40: FR-01 | F40: 씬 구성 검사 | G40: 필수 | H40: 이영노 | I40: TC-01 결과 | J40: TC-01 통과: 4개 구역과 구역별 설비 배치 확인 | K40: 46324 | L40: 46324 | O40: =IF(OR(K40="",L40=""),0,L40-K40+1-COUNTIFS(휴일!$A$2:$A$20,">="&K40,휴일!$A$2:$A$20,"<="&L40)) -> 1 | P40: =IF(OR(M40="",N40=""),0,N40-M40+1-COUNTIFS(휴일!$A$2:$A$20,">="&M40,휴일!$A$2:$A$20,"<="&N40)) -> 0 | Q40: =IF(O40=0,0,MAX(0,MIN(O40,$L$1-K40+1-COUNTIFS(휴일!$A$2:$A$20,">="&K40,휴일!$A$2:$A$20,"<="&$L$1)))) -> 0 | R40: =IF(P40=0,0,MIN(P40,O40)) -> 0 | S40: =IFERROR(Q40/O40,0) -> 0 | T40: =IFERROR(R40/O40,0) -> 0 | U40: =IF(OR(O40=0,R40=0),0,MIN(1,R40/O40)) -> 0 | V40: =U40-S40 -> 0 | W40: =IF(AND(W$5>=$K40,W$5<=$L40,COUNTIF(휴일!$A$2:$A$20,W$5)=0),IF($G40="선택","□","■"),"") | X40: =IF(AND(X$5>=$K40,X$5<=$L40,COUNTIF(휴일!$A$2:$A$20,X$5)=0),IF($G40="선택","□","■"),"") | Y40: =IF(AND(Y$5>=$K40,Y$5<=$L40,COUNTIF(휴일!$A$2:$A$20,Y$5)=0),IF($G40="선택","□","■"),"") -> ■ | Z40: =IF(AND(Z$5>=$K40,Z$5<=$L40,COUNTIF(휴일!$A$2:$A$20,Z$5)=0),IF($G40="선택","□","■"),"") | AA40: =IF(AND(AA$5>=$K40,AA$5<=$L40,COUNTIF(휴일!$A$2:$A$20,AA$5)=0),IF($G40="선택","□","■"),"") | AB40: =IF(AND(AB$5>=$K40,AB$5<=$L40,COUNTIF(휴일!$A$2:$A$20,AB$5)=0),IF($G40="선택","□","■"),"") | AC40: =IF(AND(AC$5>=$K40,AC$5<=$L40,COUNTIF(휴일!$A$2:$A$20,AC$5)=0),IF($G40="선택","□","■"),"") | AD40: =IF(AND(AD$5>=$K40,AD$5<=$L40,COUNTIF(휴일!$A$2:$A$20,AD$5)=0),IF($G40="선택","□","■"),"") | ... AF40: =IF(AND(AF$5>=$K40,AF$5<=$L40,COUNTIF(휴일!$A$2:$A$20,AF$5)=0),IF($G40="선택","□","■"),"")
B42: 3 | C42: 0.3 | D42: 공정 구현 | E42: FR-03 | F42: 박스 생성기 구현 | G42: 필수 | H42: 이영노 | I42: BoxSpawner | J42: TC-03 통과: 360×280×340mm, 2kg 박스 생성 | K42: 46325 | L42: 46325 | O42: =IF(OR(K42="",L42=""),0,L42-K42+1-COUNTIFS(휴일!$A$2:$A$20,">="&K42,휴일!$A$2:$A$20,"<="&L42)) -> 1 | P42: =IF(OR(M42="",N42=""),0,N42-M42+1-COUNTIFS(휴일!$A$2:$A$20,">="&M42,휴일!$A$2:$A$20,"<="&N42)) -> 0 | Q42: =IF(O42=0,0,MAX(0,MIN(O42,$L$1-K42+1-COUNTIFS(휴일!$A$2:$A$20,">="&K42,휴일!$A$2:$A$20,"<="&$L$1)))) -> 0 | R42: =IF(P42=0,0,MIN(P42,O42)) -> 0 | S42: =IFERROR(Q42/O42,0) -> 0 | T42: =IFERROR(R42/O42,0) -> 0 | U42: =IF(OR(O42=0,R42=0),0,MIN(1,R42/O42)) -> 0 | V42: =U42-S42 -> 0 | W42: =IF(AND(W$5>=$K42,W$5<=$L42,COUNTIF(휴일!$A$2:$A$20,W$5)=0),IF($G42="선택","□","■"),"") | X42: =IF(AND(X$5>=$K42,X$5<=$L42,COUNTIF(휴일!$A$2:$A$20,X$5)=0),IF($G42="선택","□","■"),"") | Y42: =IF(AND(Y$5>=$K42,Y$5<=$L42,COUNTIF(휴일!$A$2:$A$20,Y$5)=0),IF($G42="선택","□","■"),"") | Z42: =IF(AND(Z$5>=$K42,Z$5<=$L42,COUNTIF(휴일!$A$2:$A$20,Z$5)=0),IF($G42="선택","□","■"),"") -> ■ | AA42: =IF(AND(AA$5>=$K42,AA$5<=$L42,COUNTIF(휴일!$A$2:$A$20,AA$5)=0),IF($G42="선택","□","■"),"") | AB42: =IF(AND(AB$5>=$K42,AB$5<=$L42,COUNTIF(휴일!$A$2:$A$20,AB$5)=0),IF($G42="선택","□","■"),"") | AC42: =IF(AND(AC$5>=$K42,AC$5<=$L42,COUNTIF(휴일!$A$2:$A$20,AC$5)=0),IF($G42="선택","□","■"),"") | AD42: =IF(AND(AD$5>=$K42,AD$5<=$L42,COUNTIF(휴일!$A$2:$A$20,AD$5)=0),IF($G42="선택","□","■"),"") | ... AF42: =IF(AND(AF$5>=$K42,AF$5<=$L42,COUNTIF(휴일!$A$2:$A$20,AF$5)=0),IF($G42="선택","□","■"),"")
E43: FR-04 | F43: 투입 간격 측정과 값 확정 | G43: 필수 | H43: 이영노 | I43: 투입 간격 값 | J43: TC-04 통과: 측정 후 정한 간격으로 생성. 간격 값 기록 | K43: 46325 | L43: 46325 | O43: =IF(OR(K43="",L43=""),0,L43-K43+1-COUNTIFS(휴일!$A$2:$A$20,">="&K43,휴일!$A$2:$A$20,"<="&L43)) -> 1 | P43: =IF(OR(M43="",N43=""),0,N43-M43+1-COUNTIFS(휴일!$A$2:$A$20,">="&M43,휴일!$A$2:$A$20,"<="&N43)) -> 0 | Q43: =IF(O43=0,0,MAX(0,MIN(O43,$L$1-K43+1-COUNTIFS(휴일!$A$2:$A$20,">="&K43,휴일!$A$2:$A$20,"<="&$L$1)))) -> 0 | R43: =IF(P43=0,0,MIN(P43,O43)) -> 0 | S43: =IFERROR(Q43/O43,0) -> 0 | T43: =IFERROR(R43/O43,0) -> 0 | U43: =IF(OR(O43=0,R43=0),0,MIN(1,R43/O43)) -> 0 | V43: =U43-S43 -> 0 | W43: =IF(AND(W$5>=$K43,W$5<=$L43,COUNTIF(휴일!$A$2:$A$20,W$5)=0),IF($G43="선택","□","■"),"") | X43: =IF(AND(X$5>=$K43,X$5<=$L43,COUNTIF(휴일!$A$2:$A$20,X$5)=0),IF($G43="선택","□","■"),"") | Y43: =IF(AND(Y$5>=$K43,Y$5<=$L43,COUNTIF(휴일!$A$2:$A$20,Y$5)=0),IF($G43="선택","□","■"),"") | Z43: =IF(AND(Z$5>=$K43,Z$5<=$L43,COUNTIF(휴일!$A$2:$A$20,Z$5)=0),IF($G43="선택","□","■"),"") -> ■ | AA43: =IF(AND(AA$5>=$K43,AA$5<=$L43,COUNTIF(휴일!$A$2:$A$20,AA$5)=0),IF($G43="선택","□","■"),"") | AB43: =IF(AND(AB$5>=$K43,AB$5<=$L43,COUNTIF(휴일!$A$2:$A$20,AB$5)=0),IF($G43="선택","□","■"),"") | AC43: =IF(AND(AC$5>=$K43,AC$5<=$L43,COUNTIF(휴일!$A$2:$A$20,AC$5)=0),IF($G43="선택","□","■"),"") | AD43: =IF(AND(AD$5>=$K43,AD$5<=$L43,COUNTIF(휴일!$A$2:$A$20,AD$5)=0),IF($G43="선택","□","■"),"") | ... AF43: =IF(AND(AF$5>=$K43,AF$5<=$L43,COUNTIF(휴일!$A$2:$A$20,AF$5)=0),IF($G43="선택","□","■"),"")
E44: FR-05 | F44: 순환 메인 컨베이어 상시 구동 | G44: 필수 | H44: 이영노 | I44: MainConveyor | J44: TC-05 통과: 분기하지 못한 박스가 메인에서 계속 순환 | K44: 46325 | L44: 46325 | O44: =IF(OR(K44="",L44=""),0,L44-K44+1-COUNTIFS(휴일!$A$2:$A$20,">="&K44,휴일!$A$2:$A$20,"<="&L44)) -> 1 | P44: =IF(OR(M44="",N44=""),0,N44-M44+1-COUNTIFS(휴일!$A$2:$A$20,">="&M44,휴일!$A$2:$A$20,"<="&N44)) -> 0 | Q44: =IF(O44=0,0,MAX(0,MIN(O44,$L$1-K44+1-COUNTIFS(휴일!$A$2:$A$20,">="&K44,휴일!$A$2:$A$20,"<="&$L$1)))) -> 0 | R44: =IF(P44=0,0,MIN(P44,O44)) -> 0 | S44: =IFERROR(Q44/O44,0) -> 0 | T44: =IFERROR(R44/O44,0) -> 0 | U44: =IF(OR(O44=0,R44=0),0,MIN(1,R44/O44)) -> 0 | V44: =U44-S44 -> 0 | W44: =IF(AND(W$5>=$K44,W$5<=$L44,COUNTIF(휴일!$A$2:$A$20,W$5)=0),IF($G44="선택","□","■"),"") | X44: =IF(AND(X$5>=$K44,X$5<=$L44,COUNTIF(휴일!$A$2:$A$20,X$5)=0),IF($G44="선택","□","■"),"") | Y44: =IF(AND(Y$5>=$K44,Y$5<=$L44,COUNTIF(휴일!$A$2:$A$20,Y$5)=0),IF($G44="선택","□","■"),"") | Z44: =IF(AND(Z$5>=$K44,Z$5<=$L44,COUNTIF(휴일!$A$2:$A$20,Z$5)=0),IF($G44="선택","□","■"),"") -> ■ | AA44: =IF(AND(AA$5>=$K44,AA$5<=$L44,COUNTIF(휴일!$A$2:$A$20,AA$5)=0),IF($G44="선택","□","■"),"") | AB44: =IF(AND(AB$5>=$K44,AB$5<=$L44,COUNTIF(휴일!$A$2:$A$20,AB$5)=0),IF($G44="선택","□","■"),"") | AC44: =IF(AND(AC$5>=$K44,AC$5<=$L44,COUNTIF(휴일!$A$2:$A$20,AC$5)=0),IF($G44="선택","□","■"),"") | AD44: =IF(AND(AD$5>=$K44,AD$5<=$L44,COUNTIF(휴일!$A$2:$A$20,AD$5)=0),IF($G44="선택","□","■"),"") | ... AF44: =IF(AND(AF$5>=$K44,AF$5<=$L44,COUNTIF(휴일!$A$2:$A$20,AF$5)=0),IF($G44="선택","□","■"),"")
E45: FR-06, NFR-03 | F45: 바코드 이미지 판독 구현 | G45: 필수 | H45: 이영노 | I45: BarcodeReader | J45: TC-06 통과: L01, L02, L03 라벨에서 같은 문자열 판독. 미판독 처리는 MVP 제외 | K45: 46325 | L45: 46325 | O45: =IF(OR(K45="",L45=""),0,L45-K45+1-COUNTIFS(휴일!$A$2:$A$20,">="&K45,휴일!$A$2:$A$20,"<="&L45)) -> 1 | P45: =IF(OR(M45="",N45=""),0,N45-M45+1-COUNTIFS(휴일!$A$2:$A$20,">="&M45,휴일!$A$2:$A$20,"<="&N45)) -> 0 | Q45: =IF(O45=0,0,MAX(0,MIN(O45,$L$1-K45+1-COUNTIFS(휴일!$A$2:$A$20,">="&K45,휴일!$A$2:$A$20,"<="&$L$1)))) -> 0 | R45: =IF(P45=0,0,MIN(P45,O45)) -> 0 | S45: =IFERROR(Q45/O45,0) -> 0 | T45: =IFERROR(R45/O45,0) -> 0 | U45: =IF(OR(O45=0,R45=0),0,MIN(1,R45/O45)) -> 0 | V45: =U45-S45 -> 0 | W45: =IF(AND(W$5>=$K45,W$5<=$L45,COUNTIF(휴일!$A$2:$A$20,W$5)=0),IF($G45="선택","□","■"),"") | X45: =IF(AND(X$5>=$K45,X$5<=$L45,COUNTIF(휴일!$A$2:$A$20,X$5)=0),IF($G45="선택","□","■"),"") | Y45: =IF(AND(Y$5>=$K45,Y$5<=$L45,COUNTIF(휴일!$A$2:$A$20,Y$5)=0),IF($G45="선택","□","■"),"") | Z45: =IF(AND(Z$5>=$K45,Z$5<=$L45,COUNTIF(휴일!$A$2:$A$20,Z$5)=0),IF($G45="선택","□","■"),"") -> ■ | AA45: =IF(AND(AA$5>=$K45,AA$5<=$L45,COUNTIF(휴일!$A$2:$A$20,AA$5)=0),IF($G45="선택","□","■"),"") | AB45: =IF(AND(AB$5>=$K45,AB$5<=$L45,COUNTIF(휴일!$A$2:$A$20,AB$5)=0),IF($G45="선택","□","■"),"") | AC45: =IF(AND(AC$5>=$K45,AC$5<=$L45,COUNTIF(휴일!$A$2:$A$20,AC$5)=0),IF($G45="선택","□","■"),"") | AD45: =IF(AND(AD$5>=$K45,AD$5<=$L45,COUNTIF(휴일!$A$2:$A$20,AD$5)=0),IF($G45="선택","□","■"),"") | ... AF45: =IF(AND(AF$5>=$K45,AF$5<=$L45,COUNTIF(휴일!$A$2:$A$20,AF$5)=0),IF($G45="선택","□","■"),"")
E46: FR-07 | F46: 판독 결과에 따른 3개 레인 분기 | G46: 필수 | H46: 이영노 | I46: LaneDiverter | J46: TC-07 통과: L01, L02, L03 박스가 1, 2, 3번 레인으로 분기 | K46: 46325 | L46: 46325 | O46: =IF(OR(K46="",L46=""),0,L46-K46+1-COUNTIFS(휴일!$A$2:$A$20,">="&K46,휴일!$A$2:$A$20,"<="&L46)) -> 1 | P46: =IF(OR(M46="",N46=""),0,N46-M46+1-COUNTIFS(휴일!$A$2:$A$20,">="&M46,휴일!$A$2:$A$20,"<="&N46)) -> 0 | Q46: =IF(O46=0,0,MAX(0,MIN(O46,$L$1-K46+1-COUNTIFS(휴일!$A$2:$A$20,">="&K46,휴일!$A$2:$A$20,"<="&$L$1)))) -> 0 | R46: =IF(P46=0,0,MIN(P46,O46)) -> 0 | S46: =IFERROR(Q46/O46,0) -> 0 | T46: =IFERROR(R46/O46,0) -> 0 | U46: =IF(OR(O46=0,R46=0),0,MIN(1,R46/O46)) -> 0 | V46: =U46-S46 -> 0 | W46: =IF(AND(W$5>=$K46,W$5<=$L46,COUNTIF(휴일!$A$2:$A$20,W$5)=0),IF($G46="선택","□","■"),"") | X46: =IF(AND(X$5>=$K46,X$5<=$L46,COUNTIF(휴일!$A$2:$A$20,X$5)=0),IF($G46="선택","□","■"),"") | Y46: =IF(AND(Y$5>=$K46,Y$5<=$L46,COUNTIF(휴일!$A$2:$A$20,Y$5)=0),IF($G46="선택","□","■"),"") | Z46: =IF(AND(Z$5>=$K46,Z$5<=$L46,COUNTIF(휴일!$A$2:$A$20,Z$5)=0),IF($G46="선택","□","■"),"") -> ■ | AA46: =IF(AND(AA$5>=$K46,AA$5<=$L46,COUNTIF(휴일!$A$2:$A$20,AA$5)=0),IF($G46="선택","□","■"),"") | AB46: =IF(AND(AB$5>=$K46,AB$5<=$L46,COUNTIF(휴일!$A$2:$A$20,AB$5)=0),IF($G46="선택","□","■"),"") | AC46: =IF(AND(AC$5>=$K46,AC$5<=$L46,COUNTIF(휴일!$A$2:$A$20,AC$5)=0),IF($G46="선택","□","■"),"") | AD46: =IF(AND(AD$5>=$K46,AD$5<=$L46,COUNTIF(휴일!$A$2:$A$20,AD$5)=0),IF($G46="선택","□","■"),"") | ... AF46: =IF(AND(AF$5>=$K46,AF$5<=$L46,COUNTIF(휴일!$A$2:$A$20,AF$5)=0),IF($G46="선택","□","■"),"")
E47: FR-08 | F47: 무동력 경사 롤러 이송 | G47: 필수 | H47: 이영노 | I47: GravityRoller | J47: TC-08 통과: 구동 벨트 힘 없이 픽업 구역에 도착 | K47: 46325 | L47: 46325 | O47: =IF(OR(K47="",L47=""),0,L47-K47+1-COUNTIFS(휴일!$A$2:$A$20,">="&K47,휴일!$A$2:$A$20,"<="&L47)) -> 1 | P47: =IF(OR(M47="",N47=""),0,N47-M47+1-COUNTIFS(휴일!$A$2:$A$20,">="&M47,휴일!$A$2:$A$20,"<="&N47)) -> 0 | Q47: =IF(O47=0,0,MAX(0,MIN(O47,$L$1-K47+1-COUNTIFS(휴일!$A$2:$A$20,">="&K47,휴일!$A$2:$A$20,"<="&$L$1)))) -> 0 | R47: =IF(P47=0,0,MIN(P47,O47)) -> 0 | S47: =IFERROR(Q47/O47,0) -> 0 | T47: =IFERROR(R47/O47,0) -> 0 | U47: =IF(OR(O47=0,R47=0),0,MIN(1,R47/O47)) -> 0 | V47: =U47-S47 -> 0 | W47: =IF(AND(W$5>=$K47,W$5<=$L47,COUNTIF(휴일!$A$2:$A$20,W$5)=0),IF($G47="선택","□","■"),"") | X47: =IF(AND(X$5>=$K47,X$5<=$L47,COUNTIF(휴일!$A$2:$A$20,X$5)=0),IF($G47="선택","□","■"),"") | Y47: =IF(AND(Y$5>=$K47,Y$5<=$L47,COUNTIF(휴일!$A$2:$A$20,Y$5)=0),IF($G47="선택","□","■"),"") | Z47: =IF(AND(Z$5>=$K47,Z$5<=$L47,COUNTIF(휴일!$A$2:$A$20,Z$5)=0),IF($G47="선택","□","■"),"") -> ■ | AA47: =IF(AND(AA$5>=$K47,AA$5<=$L47,COUNTIF(휴일!$A$2:$A$20,AA$5)=0),IF($G47="선택","□","■"),"") | AB47: =IF(AND(AB$5>=$K47,AB$5<=$L47,COUNTIF(휴일!$A$2:$A$20,AB$5)=0),IF($G47="선택","□","■"),"") | AC47: =IF(AND(AC$5>=$K47,AC$5<=$L47,COUNTIF(휴일!$A$2:$A$20,AC$5)=0),IF($G47="선택","□","■"),"") | AD47: =IF(AND(AD$5>=$K47,AD$5<=$L47,COUNTIF(휴일!$A$2:$A$20,AD$5)=0),IF($G47="선택","□","■"),"") | ... AF47: =IF(AND(AF$5>=$K47,AF$5<=$L47,COUNTIF(휴일!$A$2:$A$20,AF$5)=0),IF($G47="선택","□","■"),"")
E48: FR-22 | F48: 끝 스토퍼와 측면 가이드로 픽업 위치 정렬 | G48: 필수 | H48: 이영노 | I48: PickupAligner | J48: TC-22 통과: 박스가 지정 픽업 위치와 방향에 정렬 | K48: 46325 | L48: 46325 | O48: =IF(OR(K48="",L48=""),0,L48-K48+1-COUNTIFS(휴일!$A$2:$A$20,">="&K48,휴일!$A$2:$A$20,"<="&L48)) -> 1 | P48: =IF(OR(M48="",N48=""),0,N48-M48+1-COUNTIFS(휴일!$A$2:$A$20,">="&M48,휴일!$A$2:$A$20,"<="&N48)) -> 0 | Q48: =IF(O48=0,0,MAX(0,MIN(O48,$L$1-K48+1-COUNTIFS(휴일!$A$2:$A$20,">="&K48,휴일!$A$2:$A$20,"<="&$L$1)))) -> 0 | R48: =IF(P48=0,0,MIN(P48,O48)) -> 0 | S48: =IFERROR(Q48/O48,0) -> 0 | T48: =IFERROR(R48/O48,0) -> 0 | U48: =IF(OR(O48=0,R48=0),0,MIN(1,R48/O48)) -> 0 | V48: =U48-S48 -> 0 | W48: =IF(AND(W$5>=$K48,W$5<=$L48,COUNTIF(휴일!$A$2:$A$20,W$5)=0),IF($G48="선택","□","■"),"") | X48: =IF(AND(X$5>=$K48,X$5<=$L48,COUNTIF(휴일!$A$2:$A$20,X$5)=0),IF($G48="선택","□","■"),"") | Y48: =IF(AND(Y$5>=$K48,Y$5<=$L48,COUNTIF(휴일!$A$2:$A$20,Y$5)=0),IF($G48="선택","□","■"),"") | Z48: =IF(AND(Z$5>=$K48,Z$5<=$L48,COUNTIF(휴일!$A$2:$A$20,Z$5)=0),IF($G48="선택","□","■"),"") -> ■ | AA48: =IF(AND(AA$5>=$K48,AA$5<=$L48,COUNTIF(휴일!$A$2:$A$20,AA$5)=0),IF($G48="선택","□","■"),"") | AB48: =IF(AND(AB$5>=$K48,AB$5<=$L48,COUNTIF(휴일!$A$2:$A$20,AB$5)=0),IF($G48="선택","□","■"),"") | AC48: =IF(AND(AC$5>=$K48,AC$5<=$L48,COUNTIF(휴일!$A$2:$A$20,AC$5)=0),IF($G48="선택","□","■"),"") | AD48: =IF(AND(AD$5>=$K48,AD$5<=$L48,COUNTIF(휴일!$A$2:$A$20,AD$5)=0),IF($G48="선택","□","■"),"") | ... AF48: =IF(AND(AF$5>=$K48,AF$5<=$L48,COUNTIF(휴일!$A$2:$A$20,AF$5)=0),IF($G48="선택","□","■"),"")
E49: FR-19 | F49: 중간 대기 스토퍼 개폐와 1개씩 방출 | G49: 필수 | H49: 이영노 | I49: MiddleStopper | J49: FR5 취급 중 닫힘. 다음 픽업 가능 시 1개만 방출 후 닫힘 | K49: 46325 | L49: 46325 | O49: =IF(OR(K49="",L49=""),0,L49-K49+1-COUNTIFS(휴일!$A$2:$A$20,">="&K49,휴일!$A$2:$A$20,"<="&L49)) -> 1 | P49: =IF(OR(M49="",N49=""),0,N49-M49+1-COUNTIFS(휴일!$A$2:$A$20,">="&M49,휴일!$A$2:$A$20,"<="&N49)) -> 0 | Q49: =IF(O49=0,0,MAX(0,MIN(O49,$L$1-K49+1-COUNTIFS(휴일!$A$2:$A$20,">="&K49,휴일!$A$2:$A$20,"<="&$L$1)))) -> 0 | R49: =IF(P49=0,0,MIN(P49,O49)) -> 0 | S49: =IFERROR(Q49/O49,0) -> 0 | T49: =IFERROR(R49/O49,0) -> 0 | U49: =IF(OR(O49=0,R49=0),0,MIN(1,R49/O49)) -> 0 | V49: =U49-S49 -> 0 | W49: =IF(AND(W$5>=$K49,W$5<=$L49,COUNTIF(휴일!$A$2:$A$20,W$5)=0),IF($G49="선택","□","■"),"") | X49: =IF(AND(X$5>=$K49,X$5<=$L49,COUNTIF(휴일!$A$2:$A$20,X$5)=0),IF($G49="선택","□","■"),"") | Y49: =IF(AND(Y$5>=$K49,Y$5<=$L49,COUNTIF(휴일!$A$2:$A$20,Y$5)=0),IF($G49="선택","□","■"),"") | Z49: =IF(AND(Z$5>=$K49,Z$5<=$L49,COUNTIF(휴일!$A$2:$A$20,Z$5)=0),IF($G49="선택","□","■"),"") -> ■ | AA49: =IF(AND(AA$5>=$K49,AA$5<=$L49,COUNTIF(휴일!$A$2:$A$20,AA$5)=0),IF($G49="선택","□","■"),"") | AB49: =IF(AND(AB$5>=$K49,AB$5<=$L49,COUNTIF(휴일!$A$2:$A$20,AB$5)=0),IF($G49="선택","□","■"),"") | AC49: =IF(AND(AC$5>=$K49,AC$5<=$L49,COUNTIF(휴일!$A$2:$A$20,AC$5)=0),IF($G49="선택","□","■"),"") | AD49: =IF(AND(AD$5>=$K49,AD$5<=$L49,COUNTIF(휴일!$A$2:$A$20,AD$5)=0),IF($G49="선택","□","■"),"") | ... AF49: =IF(AND(AF$5>=$K49,AF$5<=$L49,COUNTIF(휴일!$A$2:$A$20,AF$5)=0),IF($G49="선택","□","■"),"")
E50: FR-09 | F50: FR5 흡착과 해제 | G50: 필수 | H50: 이영노 | I50: VacuumGripper | J50: TC-09 통과: 흡착점에서 부착, 적재점에서 해제 | K50: 46325 | L50: 46325 | O50: =IF(OR(K50="",L50=""),0,L50-K50+1-COUNTIFS(휴일!$A$2:$A$20,">="&K50,휴일!$A$2:$A$20,"<="&L50)) -> 1 | P50: =IF(OR(M50="",N50=""),0,N50-M50+1-COUNTIFS(휴일!$A$2:$A$20,">="&M50,휴일!$A$2:$A$20,"<="&N50)) -> 0 | Q50: =IF(O50=0,0,MAX(0,MIN(O50,$L$1-K50+1-COUNTIFS(휴일!$A$2:$A$20,">="&K50,휴일!$A$2:$A$20,"<="&$L$1)))) -> 0 | R50: =IF(P50=0,0,MIN(P50,O50)) -> 0 | S50: =IFERROR(Q50/O50,0) -> 0 | T50: =IFERROR(R50/O50,0) -> 0 | U50: =IF(OR(O50=0,R50=0),0,MIN(1,R50/O50)) -> 0 | V50: =U50-S50 -> 0 | W50: =IF(AND(W$5>=$K50,W$5<=$L50,COUNTIF(휴일!$A$2:$A$20,W$5)=0),IF($G50="선택","□","■"),"") | X50: =IF(AND(X$5>=$K50,X$5<=$L50,COUNTIF(휴일!$A$2:$A$20,X$5)=0),IF($G50="선택","□","■"),"") | Y50: =IF(AND(Y$5>=$K50,Y$5<=$L50,COUNTIF(휴일!$A$2:$A$20,Y$5)=0),IF($G50="선택","□","■"),"") | Z50: =IF(AND(Z$5>=$K50,Z$5<=$L50,COUNTIF(휴일!$A$2:$A$20,Z$5)=0),IF($G50="선택","□","■"),"") -> ■ | AA50: =IF(AND(AA$5>=$K50,AA$5<=$L50,COUNTIF(휴일!$A$2:$A$20,AA$5)=0),IF($G50="선택","□","■"),"") | AB50: =IF(AND(AB$5>=$K50,AB$5<=$L50,COUNTIF(휴일!$A$2:$A$20,AB$5)=0),IF($G50="선택","□","■"),"") | AC50: =IF(AND(AC$5>=$K50,AC$5<=$L50,COUNTIF(휴일!$A$2:$A$20,AC$5)=0),IF($G50="선택","□","■"),"") | AD50: =IF(AND(AD$5>=$K50,AD$5<=$L50,COUNTIF(휴일!$A$2:$A$20,AD$5)=0),IF($G50="선택","□","■"),"") | ... AF50: =IF(AND(AF$5>=$K50,AF$5<=$L50,COUNTIF(휴일!$A$2:$A$20,AF$5)=0),IF($G50="선택","□","■"),"")
...

Sheet 휴일
A1: 휴일 | B1: 내용
A2: 46326 | B2: 휴일 (토)
A3: 46327 | B3: 휴일 (일)
